<mujoco model="a3_t2d0_loop">
  <compiler angle="radian" meshdir="../meshes" autolimits="true"/>
  <option timestep="0.001"/>

  <visual>
    <global azimuth="150" elevation="-20"/>
    <headlight ambient="0.3 0.3 0.3" diffuse="0.6 0.6 0.6" specular="0 0 0"/>
    <scale forcewidth="0.03" contactwidth="0.01" contactheight="0.02" com="1" framelength="0.6" framewidth="0.05"/>
    <rgba haze="0.15 0.25 0.35 1" com="0.502 1 0 0.5" contactpoint="1 1 0.6 0.4" contactforce="0.98 0.4 0.4 1"/>
  </visual>

  <statistic extent="1.1" center="0 0 0.55"/>

  <default>
    <geom contype="0" conaffinity="0" friction="1 1" solref="0.005"/>
    <default class="visual">
      <geom group="2" type="mesh" density="0" contype="0" conaffinity="0"/>
    </default>
    <equality solref="0.005"/>
    <default class="zhiyuan"/>
    <default class="collision">
      <geom type="capsule" contype="1" group="3"/>
      <default class="collision-left">
        <geom contype="2" conaffinity="4"/>
      </default>
      <default class="collision-right">
        <geom contype="4" conaffinity="2"/>
      </default>
    </default>
  </default>

  <asset>
    <texture type="skybox" name="skybox" builtin="gradient" mark="random" rgb1="0.2 0.3 0.4" rgb2="0 0 0" markrgb="1 1 1" random="0.001" width="1000" height="6000"/>
    <texture type="2d" name="groundplane" builtin="checker" mark="edge" rgb1="0.2 0.3 0.4" rgb2="0.1 0.2 0.3" markrgb="0.8 0.8 0.8" width="1000" height="1000"/>
    <material name="metalic silver" rgba="0.59 0.59 0.65 1"/>
    <material name="metalic black" rgba="0.235294 0.235294 0.235294 1"/>
    <material name="groundplane" texture="groundplane" texuniform="true" texrepeat="5 5" reflectance="0.2"/>

    <mesh name="pelvis_link" content_type="model/stl" file="pelvis_link.STL"/>
    <mesh name="waist_yaw_Link" content_type="model/stl" file="waist_yaw_Link.STL"/>
    <mesh name="waist_roll_Link" content_type="model/stl" file="waist_roll_Link.STL"/>
    <mesh name="torso_Link" content_type="model/stl" file="torso_Link.STL"/>
    <mesh name="head_Link" content_type="model/stl" file="head_Link.STL"/>
    <mesh name="left_shoulder_pitch_Link" content_type="model/stl" file="left_shoulder_pitch_Link.STL"/>
    <mesh name="left_shoulder_roll_Link" content_type="model/stl" file="left_shoulder_roll_Link.STL"/>
    <mesh name="left_shoulder_yaw_Link" content_type="model/stl" file="left_shoulder_yaw_Link.STL"/>
    <mesh name="left_elbow_Link" content_type="model/stl" file="left_elbow_Link.STL"/>
    <mesh name="left_wrist_roll_Link" content_type="model/stl" file="left_wrist_roll_Link.STL"/>
    <mesh name="left_wrist_pitch_Link" content_type="model/stl" file="left_wrist_pitch_Link.STL"/>
    <mesh name="left_wrist_yaw_Link" content_type="model/stl" file="left_wrist_yaw_Link.STL"/>
    <mesh name="left_hand_palm_Link" content_type="model/stl" file="left_hand_palm_Link.STL"/>
    <mesh name="left_hand_fist_Link" content_type="model/stl" file="left_hand_fist.STL"/>
    <mesh name="left_hand_fist_hull" content_type="model/stl" file="left_hand_fist_hull.STL"/>
    <mesh name="right_shoulder_pitch_Link" content_type="model/stl" file="right_shoulder_pitch_Link.STL"/>
    <mesh name="right_shoulder_roll_Link" content_type="model/stl" file="right_shoulder_roll_Link.STL"/>
    <mesh name="right_shoulder_yaw_Link" content_type="model/stl" file="right_shoulder_yaw_Link.STL"/>
    <mesh name="right_elbow_Link" content_type="model/stl" file="right_elbow_Link.STL"/>
    <mesh name="right_wrist_roll_Link" content_type="model/stl" file="right_wrist_roll_Link.STL"/>
    <mesh name="right_wrist_pitch_Link" content_type="model/stl" file="right_wrist_pitch_Link.STL"/>
    <mesh name="right_wrist_yaw_Link" content_type="model/stl" file="right_wrist_yaw_Link.STL"/>
    <mesh name="right_hand_palm_Link" content_type="model/stl" file="right_hand_palm_Link.STL"/>
    <mesh name="right_hand_fist_Link" content_type="model/stl" file="right_hand_fist.STL"/>
    <mesh name="right_hand_fist_hull" content_type="model/stl" file="right_hand_fist_hull.STL"/>
    <mesh name="left_hip_pitch_Link" content_type="model/stl" file="left_hip_pitch_Link.STL"/>
    <mesh name="left_hip_roll_Link" content_type="model/stl" file="left_hip_roll_Link.STL"/>
    <mesh name="left_hip_yaw_Link" content_type="model/stl" file="left_hip_yaw_Link.STL"/>
    <mesh name="left_knee_Link" content_type="model/stl" file="left_knee_Link.STL"/>
    <mesh name="left_ankle_pitch_Link" content_type="model/stl" file="left_ankle_pitch_Link.STL"/>
    <mesh name="left_ankle_roll_Link" content_type="model/stl" file="left_ankle_roll_Link.STL"/>
    <mesh name="right_hip_pitch_Link" content_type="model/stl" file="right_hip_pitch_Link.STL"/>
    <mesh name="right_hip_roll_Link" content_type="model/stl" file="right_hip_roll_Link.STL"/>
    <mesh name="right_hip_yaw_Link" content_type="model/stl" file="right_hip_yaw_Link.STL"/>
    <mesh name="right_knee_Link" content_type="model/stl" file="right_knee_Link.STL"/>
    <mesh name="right_ankle_pitch_Link" content_type="model/stl" file="right_ankle_pitch_Link.STL"/>
    <mesh name="right_ankle_roll_Link" content_type="model/stl" file="right_ankle_roll_Link.STL"/>

    <mesh name="left_ankle_motor_up_Link" content_type="model/stl" file="../meshes/left_ankle_motor_up_Link.STL"/>
    <mesh name="left_ankle_rod_long_up_Link" content_type="model/stl" file="../meshes/left_ankle_rod_long_up_Link.STL"/>
    <mesh name="left_ankle_motor_down_Link" content_type="model/stl" file="../meshes/left_ankle_motor_down_Link.STL"/>
    <mesh name="left_ankle_rod_short_up_Link" content_type="model/stl" file="../meshes/left_ankle_rod_short_up_Link.STL"/>
    <mesh name="right_ankle_motor_up_Link" content_type="model/stl" file="../meshes/right_ankle_motor_up_Link.STL"/>
    <mesh name="right_ankle_rod_long_up_Link" content_type="model/stl" file="../meshes/right_ankle_rod_long_up_Link.STL"/>
    <mesh name="right_ankle_motor_down_Link" content_type="model/stl" file="../meshes/right_ankle_motor_down_Link.STL"/>
    <mesh name="right_ankle_rod_short_up_Link" content_type="model/stl" file="../meshes/right_ankle_rod_short_up_Link.STL"/>

    <!-- <mesh name="left_waist_rod_down_Link" content_type="model/stl" file="left_waist_rod_down_Link.STL"/> -->
    <mesh name="left_waist_rod_up_Link" content_type="model/stl" file="../meshes/left_waist_rod_up_Link.STL"/>
    <mesh name="left_waist_motor_Link" content_type="model/stl" file="../meshes/left_waist_motor_Link.STL"/>
    <!-- <mesh name="right_waist_rod_down_Link" content_type="model/stl" file="right_waist_rod_down_Link.STL"/> -->
    <mesh name="right_waist_rod_up_Link" content_type="model/stl" file="../meshes/right_waist_rod_up_Link.STL"/>
    <mesh name="right_waist_motor_Link" content_type="model/stl" file="../meshes/right_waist_motor_Link.STL"/>
  </asset>

  <worldbody>
    <geom name="floor" size="300 300 0.125" type="plane" conaffinity="7" material="groundplane"/>
    <light pos="0 0 10" dir="0 0 -1" directional="true"/>
    <light name="spotlight" target="pelvis_link" pos="0 -1 2" dir="0 0 -1" mode="targetbodycom"/>
    <body name="pelvis_link" pos="0 0 1.1">
      <!-- <light pos="0 0 2" mode="trackcom"/> -->
      <!-- <camera name="tracking" pos="1.734 -1.135 0.35" xyaxes="0.552 0.834 -0.000 -0.170 0.112 0.979" mode="trackcom"/> -->
      <inertial pos="-0.00172504 0.000830241 -0.12641" quat="0.997276 0.0734874 0.00605114 -0.0019108" mass="5.01797" diaginertia="0.0246338 0.0181068 0.0155254"/>
      <joint name="floating_joint" type="free" range="-2.61799 2.61799" actuatorfrcrange="-220 220" actuatorfrclimited="true"/>
      <geom class="visual" type="mesh" rgba="0.101961 0.101961 0.101961 1" mesh="pelvis_link"/>
      <geom name="pelvis_collision" class="collision" size="0.07 0.046" pos="0 0 -0.15" quat="0.707106781 0.707106781 0 0" type="capsule" rgba="1 0 0 1"/>
      <site name="imu_in_pelvis" size="0.01" pos="-0.00287 0 -0.21015"/>
      <body name="left_hip_pitch_Link" pos="0 0.12 -0.176454" quat="0.991445 -0.130526 0 0">
        <inertial pos="0.00267871 -0.00243539 -0.0564427" quat="0.989925 0.141081 0.0106521 0.00563997" mass="1.77895" diaginertia="0.00367875 0.00301933 0.00200903"/>
        <joint name="left_hip_pitch_joint" pos="0 0 0" axis="0 1 0" range="-2.68781 2.93215" actuatorfrcrange="-220 220" actuatorfrclimited="true" damping="1"/>
        <geom class="visual" type="mesh" rgba="0.2 0.2 0.2 1" mesh="left_hip_pitch_Link"/>
        <body name="left_hip_roll_Link" pos="0.0163026 0.0168285 -0.0628047" quat="0.991445 0.130526 0 0">
          <inertial pos="0.012662 -0.00178224 -0.0534708" quat="0.983422 -0.0393403 0.176873 0.0070033" mass="0.352065" diaginertia="0.000991618 0.000853074 0.000576478"/>
          <joint name="left_hip_roll_joint" pos="0 0 0" axis="1 0 0" range="-0.698132 1.22173" actuatorfrcrange="-220 220" actuatorfrclimited="true" damping="1"/>
          <geom class="visual" type="mesh" rgba="0.752941 0.752941 0.752941 1" mesh="left_hip_roll_Link"/>
          <geom name="left_hip_collision" class="collision" size="0.046" pos="-0.018 -0.015 -0.01" type="sphere" rgba="1 0 0 1"/>
          <body name="left_hip_yaw_Link">
            <inertial pos="-0.00612772 -0.00144301 -0.275261" quat="0.700678 0.0238877 0.0299847 0.712447" mass="4.54364" diaginertia="0.0679422 0.0664219 0.00839615"/>
            <joint name="left_hip_yaw_joint" pos="0 0 0" axis="0 0 1" range="-2.75762 2.75762" actuatorfrcrange="-220 220" actuatorfrclimited="true" damping="1"/>
            <geom class="visual" type="mesh" rgba="0.752941 0.752941 0.752941 1" mesh="left_hip_yaw_Link"/>
            <geom name="left_thigh_collision" class="collision" size="0.054 0.07" pos="0.0065 0.0 -0.19" type="capsule" rgba="1 0 0 1"/>
            <body name="left_knee_Link" pos="-0.0163026 0 -0.37">
              <inertial pos="-0.00317169 -0.00065704 -0.173444" quat="0.99911 0.00454426 0.0215255 -0.0359899" mass="3.07101" diaginertia="0.0380682 0.0371294 0.00498658"/>
              <joint name="left_knee_joint" pos="0 0 0" axis="0 1 0" range="-0.122173 2.44346" actuatorfrcrange="-320 320" actuatorfrclimited="true" damping="1.5"/>
              <geom class="visual" type="mesh" rgba="0.752941 0.752941 0.752941 1" mesh="left_knee_Link"/>
              <geom name="left_shin_collision" class="collision" size="0.057 0.1" pos="0.0 0.0 -0.22" type="capsule" rgba="1 0 0 1"/>
              <body name="left_ankle_pitch_Link" pos="0 0.000200014 -0.415">
                <inertial pos="0 0 -0.00028903" quat="0.5 0.5 -0.5 0.5" mass="0.116844" diaginertia="3.362e-05 2.714e-05 1.074e-05"/>
                <joint name="left_ankle_pitch_joint" pos="0 0 0" axis="0 1 0" range="-0.907571 0.523599" actuatorfrcrange="-115 115" actuatorfrclimited="true" damping="0.55"/>
                <geom class="visual" type="mesh" rgba="0.752941 0.752941 0.752941 1" mesh="left_ankle_pitch_Link"/>
                <body name="left_ankle_roll_Link">
                  <inertial pos="0.0145172 2.44e-06 -0.0276092" quat="2.93533e-06 0.743627 3.78776e-05 0.668594" mass="0.686654" diaginertia="0.00343289 0.00331387 0.000689982"/>
                  <joint name="left_ankle_roll_joint" pos="0 0 0" axis="1 0 0" range="-0.349066 0.349066" actuatorfrcrange="-54 54" actuatorfrclimited="true" damping="0.55"/>
                  <geom class="visual" type="mesh" rgba="0.2 0.2 0.2 1" mesh="left_ankle_roll_Link"/>
                  <site name="left_foot" rgba="1 0 0 1" pos="0.04 0 -0.067"/>
                  <geom name="left_foot1_collision" class="collision" size="0.002" pos="0.175 0 -0.054" type="sphere"/>
                  <geom name="left_foot2_collision" class="collision" size="0.002" pos="-0.09 0 -0.066" type="sphere"/>
                  <geom name="left_foot3_collision" class="collision" size="0.002" pos="0.135 0.046 -0.063" type="sphere"/>
                  <geom name="left_foot4_collision" class="collision" size="0.002" pos="0.135 -0.046 -0.063" type="sphere"/>
                  <geom name="left_foot5_collision" class="collision" size="0.002" pos="0.065 0.053 -0.066" type="sphere"/>
                  <geom name="left_foot6_collision" class="collision" size="0.002" pos="0.065 -0.053 -0.066" type="sphere"/>
                  <geom name="left_foot7_collision" class="collision" size="0.002" pos="-0.055 0.045 -0.066" type="sphere"/>
                  <geom name="left_foot8_collision" class="collision" size="0.002" pos="-0.055 -0.045 -0.066" type="sphere"/>
                  <geom name="left_foot9_collision" class="collision" size="0.002" pos="0.1 0.053 -0.0655" type="sphere"/>
                  <geom name="left_foot10_collision" class="collision" size="0.002" pos="0.1 -0.053 -0.0655" type="sphere"/>
                  <geom name="left_foot11_collision" class="collision" size="0.002" pos="0.065 0 -0.066" type="sphere"/>
                  <geom name="left_foot12_collision" class="collision" size="0.002" pos="0 -0.026 -0.055" type="sphere"/>
                  <geom name="left_foot13_collision" class="collision" size="0.002" pos="0 0.026 -0.055" type="sphere"/>
                </body>
              </body>
              <body name="left_ankle_motor_up_Link" pos="0 0 -0.125">
                <inertial pos="-0.0331460632638968 -0.0105050149053889 0.00356667304724829" mass="0.0443314976757638" fullinertia="1.51909791547363E-05 7.02538522840495E-06 1.07776978127551E-05 1.46920289323126E-06 -7.24571855484113E-07 -1.57797784991339E-06"/>
                <geom class="visual" type="mesh" rgba="0.8902 0.8902 0.91373 1" mesh="left_ankle_motor_up_Link"/>
                <joint name="left_ankle_motor_up_joint" pos="0 0 0" axis="-1 0 0" range="-1.5 1.5" actuatorfrcrange="-60 60" damping="0.25" actuatorfrclimited="true"/>
                <body name="left_ankle_rod_long_up_Link" pos="-0.0415000000000006 -0.0344412641467716 0.00622891033586917">
                  <inertial pos="0.00112007427085541 0.00696756846739216 -0.163939109830067" mass="0.177412405439732" fullinertia="0.00137150399979244 0.00136967608792899 6.0932003201601E-06 3.44517632106087E-07 -9.33148286380617E-06 -5.80565801769861E-05"/>
                  <geom class="visual" type="mesh" rgba="0.8902 0.8902 0.91373 1" mesh="left_ankle_rod_long_up_Link"/>
                  <joint name="left_ankle_rod_long_up_joint" pos="0 0 0" type="ball" damping="0.25" limited = 'false'/>
                </body>
              </body>
              <body name="left_ankle_motor_down_Link" pos="0 0 -0.21">
                <inertial pos="-0.0251458725703578 0.0105303937526887 0.00350954172033863" mass="0.044332657278429" fullinertia="1.51854283890655E-05 7.00682466343355E-06 1.07907929066816E-05 -1.47171694968547E-06 -7.16277049400447E-07 1.55301335425489E-06"/>
                <geom class="visual" type="mesh" rgba="0.8902 0.8902 0.91373 1" mesh="left_ankle_motor_down_Link"/>
                <joint name="left_ankle_motor_down_joint" pos="0 0 0" axis="-1 0 0" range="-1.5 1.5" actuatorfrcrange="-60 60" damping="0.25" actuatorfrclimited="true"/>
                <body name="left_ankle_rod_short_up_Link" pos="-0.0335000000000012 0.0344750976533253 0.00603884440879429">
                  <inertial pos="-0.00347083772498318 -0.00721649998436245 -0.12005560764595" mass="0.135842625721835" fullinertia="0.000543530013532555 0.000542726288482748 6.52001586890016E-06 9.37590090373021E-07 1.55669059195413E-05 3.24051437004143E-05"/>
                  <geom class="visual" type="mesh" rgba="0.8902 0.8902 0.91373 1" mesh="left_ankle_rod_short_up_Link"/>
                  <joint name="left_ankle_rod_short_up_joint" pos="0 0 0" type="ball" damping="0.25" limited = 'false'/>
                </body>
              </body>
            </body>
          </body>
        </body>
      </body>
      <body name="right_hip_pitch_Link" pos="0 -0.12 -0.176454" quat="0.991445 0.130526 0 0">
        <inertial pos="0.00268023 0.00240798 -0.0564328" quat="0.989984 -0.140685 0.0102924 -0.00585303" mass="1.77802" diaginertia="0.00367521 0.00301801 0.00200643"/>
        <joint name="right_hip_pitch_joint" pos="0 0 0" axis="0 1 0" range="-2.68781 2.93215" actuatorfrcrange="-220 220" actuatorfrclimited="true" damping="1"/>
        <geom type="mesh" rgba="0.2 0.2 0.2 1" mesh="right_hip_pitch_Link"/>
        <body name="right_hip_roll_Link" pos="0.0163026 -0.0168285 -0.0628047" quat="0.991445 -0.130526 0 0">
          <inertial pos="0.0126598 0.0017836 -0.0534713" quat="0.983435 0.0393323 0.176806 -0.00697535" mass="0.352044" diaginertia="0.000991531 0.000853042 0.000576476"/>
          <joint name="right_hip_roll_joint" pos="0 0 0" axis="1 0 0" range="-1.22173 0.698132" actuatorfrcrange="-220 220" actuatorfrclimited="true" damping="1"/>
          <geom class="visual" type="mesh" rgba="0.752941 0.752941 0.752941 1" mesh="right_hip_roll_Link"/>
          <geom name="right_hip_collision" class="collision" size="0.046" pos="-0.018 0.015 -0.01" type="sphere" rgba="1 0 0 1"/>
          <body name="right_hip_yaw_Link">
            <inertial pos="-0.00612676 0.00126124 -0.275388" quat="0.710029 0.030692 0.0227878 0.703134" mass="4.53939" diaginertia="0.0678994 0.0663606 0.00841113"/>
            <joint name="right_hip_yaw_joint" pos="0 0 0" axis="0 0 1" range="-2.75762 2.75762" actuatorfrcrange="-220 220" actuatorfrclimited="true" damping="1"/>
            <geom class="visual" type="mesh" rgba="0.752941 0.752941 0.752941 1" mesh="right_hip_yaw_Link"/>
            <geom name="right_thigh_collision" class="collision" size="0.054 0.07" pos="0.0065 0.0 -0.19" type="capsule" rgba="1 0 0 1"/>
            <body name="right_knee_Link" pos="-0.0163026 0 -0.37">
              <inertial pos="-0.00320407 0.00063549 -0.173543" quat="0.999152 -0.00450857 0.0215665 0.0347871" mass="3.08106" diaginertia="0.0380958 0.0371466 0.00499981"/>
              <joint name="right_knee_joint" pos="0 0 0" axis="0 1 0" range="-0.122173 2.44346" actuatorfrcrange="-320 320" actuatorfrclimited="true" damping="1.5"/>
              <geom class="visual" type="mesh" rgba="0.752941 0.752941 0.752941 1" mesh="right_knee_Link"/>
              <geom name="right_shin_collision" class="collision" size="0.057 0.1" pos="0.0 0.0 -0.22" type="capsule" rgba="1 0 0 1"/>
              <body name="right_ankle_pitch_Link" pos="0 -0.000200014 -0.415">
                <inertial pos="0 0 -0.00028903" quat="0.5 0.5 -0.5 0.5" mass="0.116844" diaginertia="3.362e-05 2.714e-05 1.074e-05"/>
                <joint name="right_ankle_pitch_joint" pos="0 0 0" axis="0 1 0" range="-0.907571 0.523599" actuatorfrcrange="-115 115" actuatorfrclimited="true" damping="0.55"/>
                <geom class="visual" type="mesh" rgba="0.752941 0.752941 0.752941 1" mesh="right_ankle_pitch_Link"/>
                <body name="right_ankle_roll_Link">
                  <inertial pos="0.0145172 2.44e-06 -0.0376092" quat="2.93533e-06 0.743627 3.78776e-05 0.668594" mass="0.686654" diaginertia="0.00343289 0.00331387 0.000689982"/>
                  <joint name="right_ankle_roll_joint" pos="0 0 0" axis="1 0 0" range="-0.349066 0.349066" actuatorfrcrange="-54 54" actuatorfrclimited="true" damping="0.55"/>
                  <geom class="visual" type="mesh" rgba="0.2 0.2 0.2 1" mesh="right_ankle_roll_Link"/>
                  <site name="right_foot" rgba="1 0 0 1" pos="0.04 0 -0.067"/>
                  <geom name="right_foot1_collision" class="collision" size="0.002" pos="0.175 0 -0.054" type="sphere"/>
                  <geom name="right_foot2_collision" class="collision" size="0.002" pos="-0.09 0 -0.066" type="sphere"/>
                  <geom name="right_foot3_collision" class="collision" size="0.002" pos="0.135 0.046 -0.063" type="sphere"/>
                  <geom name="right_foot4_collision" class="collision" size="0.002" pos="0.135 -0.046 -0.063" type="sphere"/>
                  <geom name="right_foot5_collision" class="collision" size="0.002" pos="0.065 0.053 -0.066" type="sphere"/>
                  <geom name="right_foot6_collision" class="collision" size="0.002" pos="0.065 -0.053 -0.066" type="sphere"/>
                  <geom name="right_foot7_collision" class="collision" size="0.002" pos="-0.055 0.045 -0.066" type="sphere"/>
                  <geom name="right_foot8_collision" class="collision" size="0.002" pos="-0.055 -0.045 -0.066" type="sphere"/>
                  <geom name="right_foot9_collision" class="collision" size="0.002" pos="0.1 0.053 -0.0655" type="sphere"/>
                  <geom name="right_foot10_collision" class="collision" size="0.002" pos="0.1 -0.053 -0.0655" type="sphere"/>
                  <geom name="right_foot11_collision" class="collision" size="0.002" pos="0.065 0 -0.066" type="sphere"/>
                  <geom name="right_foot12_collision" class="collision" size="0.002" pos="0 -0.026 -0.055" type="sphere"/>
                  <geom name="right_foot13_collision" class="collision" size="0.002" pos="0 0.026 -0.055" type="sphere"/>
                </body>
              </body>
              <body name="right_ankle_motor_up_Link" pos="0 0 -0.125">
                <inertial pos="-0.0331460632638968 -0.0105050149053889 0.00356667304724829" mass="0.0443314976757638" fullinertia="1.51909791547363E-05 7.02538522840495E-06 1.07776978127551E-05 1.46920289323126E-06 -7.24571855484113E-07 -1.57797784991339E-06"/>
                <geom class="visual" type="mesh" rgba="0.8902 0.8902 0.91373 1" mesh="right_ankle_motor_up_Link"/>
                <joint name="right_ankle_motor_up_joint" pos="0 0 0" axis="-1 0 0" range="-1.5 1.5" actuatorfrcrange="-60 60" damping="0.25" actuatorfrclimited="true"/>
                <body name="right_ankle_rod_long_up_Link" pos="-0.0415000000000006 0.0344412641467716 0.00622891033586917">
                  <inertial pos="0.00112007427085541 0.00696756846739216 -0.163939109830067" mass="0.177412405439732" fullinertia="0.00137150399979244 0.00136967608792899 6.0932003201601E-06 3.44517632106087E-07 -9.33148286380617E-06 -5.80565801769861E-05"/>
                  <geom class="visual" type="mesh" rgba="0.8902 0.8902 0.91373 1" mesh="right_ankle_rod_long_up_Link"/>
                  <joint name="right_ankle_rod_long_up_joint" pos="0 0 0" type="ball" damping="0.25" limited = 'false'/>
                </body>
              </body>
              <body name="right_ankle_motor_down_Link" pos="0 0 -0.21">
                <inertial pos="-0.0251458725703578 0.0105303937526887 0.00350954172033863" mass="0.044332657278429" fullinertia="1.51854283890655E-05 7.00682466343355E-06 1.07907929066816E-05 -1.47171694968547E-06 -7.16277049400447E-07 1.55301335425489E-06"/>
                <geom class="visual" type="mesh" rgba="0.8902 0.8902 0.91373 1" mesh="right_ankle_motor_down_Link"/>
                <joint name="right_ankle_motor_down_joint" pos="0 0 0" axis="-1 0 0" range="-1.5 1.5" actuatorfrcrange="-60 60" damping="0.25" actuatorfrclimited="true"/>
                <body name="right_ankle_rod_short_up_Link" pos="-0.0335000000000012 -0.0344750976533253 0.00603884440879429">
                  <inertial pos="-0.00347083772498318 -0.00721649998436245 -0.12005560764595" mass="0.135842625721835" fullinertia="0.000543530013532555 0.000542726288482748 6.52001586890016E-06 9.37590090373021E-07 1.55669059195413E-05 3.24051437004143E-05"/>
                  <geom class="visual" type="mesh" rgba="0.8902 0.8902 0.91373 1" mesh="right_ankle_rod_short_up_Link"/>
                  <joint name="right_ankle_rod_short_up_joint" pos="0 0 0" type="ball" damping="0.25" limited = 'false'/>
                </body>
              </body>
            </body>
          </body>
        </body>
      </body>
      <body name="waist_yaw_Link">
        <inertial pos="-0.00087176 -0.00013308 -0.0195765" quat="-0.00264398 0.751816 -0.00125183 0.659366" mass="0.269779" diaginertia="0.000378112 0.000287238 0.00017602"/>
        <joint name="waist_yaw_joint" pos="0 0 0" axis="0 0 1" range="-2.61799 2.61799" actuatorfrcrange="-220 220" actuatorfrclimited="true" damping="1"/>
        <geom class="visual" type="mesh" rgba="0.8902 0.8902 0.91373 1" mesh="waist_yaw_Link"/>
        <body name="waist_pitch_Link">
          <inertial pos="0 0 -0.00250026" quat="0.5 0.5 -0.5 0.5" mass="0.0883729" diaginertia="2.292e-05 1.401e-05 1.401e-05"/>
          <joint name="waist_roll_joint" pos="-0.02 0 0" axis="1 0 0" range="-0.488692 0.418879" actuatorfrcrange="-46 46" actuatorfrclimited="true" damping="1.5"/>
          <geom class="visual" type="mesh" rgba="1 1 1 1" mesh="waist_roll_Link"/>
          <body name="torso_Link" pos="-0.02 0 0.005">
            <inertial pos="0.0147435 -0.00120831 0.191318" quat="0.999801 -0.00200141 -0.0198 -0.00132415" mass="17.5232" diaginertia="0.254606 0.203742 0.138076"/>
            <joint name="waist_pitch_joint" pos="0 0 0" axis="0 1 0" range="-0.349066 0.349066" actuatorfrcrange="-118 118" actuatorfrclimited="true" damping="1.5"/>
            <geom class="visual" type="mesh" rgba="0.792157 0.819608 0.933333 1" mesh="torso_Link"/>
            <geom name="torso_collision" class="collision" type="mesh" mesh="torso_Link"/>
            <site name="imu_in_torso" size="0.01" pos="0 0 0.11185"/>

            <body name="left_waist_motor_Link" pos="0 0.059 0.075">
              <inertial pos="0.0402917 -0.0130511 0.00227443" quat="0.658103 0.728263 -0.190643 0.0137418" mass="0.0569761" diaginertia="1.91995e-05 1.52162e-05 7.97008e-06"/>
              <joint name="left_waist_motor_joint" pos="0 0 0" axis="1 0 0" range="-1.8 1.8" actuatorfrcrange="-60 60" actuatorfrclimited="true" damping="1"/>
              <geom class="visual" type="mesh" rgba="0.752941 0.752941 0.752941 1" mesh="left_waist_motor_Link"/>
              <body name="left_waist_rod_up_Link" pos="0.0498 -0.0399595 0.00179872">
                <inertial pos="0.0026 0.00172977 -0.0483994" quat="0.99864 -0.0191319 0.0261834 -0.0408262" mass="0.0917876" diaginertia="6.757e-05 6.61267e-05 2.75193e-06"/>
                <joint name="left_waist_rod_up_joint" pos="0 0 0" type="ball" damping="1" limited = 'false'/>
                <geom class="visual" type="mesh" rgba="0.752941 0.752941 0.752941 1" mesh="left_waist_rod_up_Link"/>
                <body name="left_waist_rod_down_Link" pos="0.0052 0.00345955 -0.0967987">
                  <inertial pos="3.36832e-09 -1.19858e-08 8.58382e-09" quat="0.735086 0.677974 0 0" mass="0.0116707" diaginertia="3.14172e-07 3.04666e-07 3.04641e-07"/>
                </body>
              </body>
            </body>
            <body name="right_waist_motor_Link" pos="0 -0.059 0.075">
              <inertial pos="0.0402927 0.0130501 0.00227282" quat="0.728229 0.658135 -0.0137497 0.190664" mass="0.056968" diaginertia="1.91996e-05 1.52151e-05 7.96971e-06"/>
              <joint name="right_waist_motor_joint" pos="0 0 0" axis="1 0 0" range="-1.8 1.8" actuatorfrcrange="-60 60" actuatorfrclimited="true" damping="1"/>
              <geom class="visual" type="mesh" rgba="0.752941 0.752941 0.752941 1" mesh="right_waist_motor_Link"/>
              <body name="right_waist_rod_up_Link" pos="0.0498 0.0399595 0.00179873">
                <inertial pos="0.00260001 -0.00172977 -0.0483994" quat="0.982901 0.0229021 0.02334 0.181211" mass="0.0917876" diaginertia="6.74578e-05 6.62411e-05 2.74964e-06"/>
                <joint name="right_waist_rod_up_joint" pos="0 0 0" type="ball" damping="1" limited = 'false'/>
                <geom class="visual" type="mesh" rgba="0.752941 0.752941 0.752941 1" mesh="right_waist_rod_up_Link"/>
                <body name="right_waist_rod_down_Link" pos="0.0052 -0.00345953 -0.0967987">
                  <inertial pos="5.59319e-09 -9.73567e-09 4.81343e-10" quat="0.872387 0.488815 0 0" mass="0.0116707" diaginertia="3.14172e-07 3.04666e-07 3.04641e-07"/>
                </body>
              </body>
            </body>

            <body name="head_Link" pos="0.0303 0 0.28896">
              <inertial pos="0.0244828 0.00023542 0.225908" quat="0.70913 0.0133707 0.0125505 0.704839" mass="1.49705" diaginertia="0.0145608 0.0134343 0.00677444"/>
              <joint name="head_joint" pos="0 0 0" axis="0 0 1" range="-0.785398 0.785398" actuatorfrcrange="-6 6" actuatorfrclimited="true" damping="1"/>
              <geom class="visual" type="mesh" rgba="0.278431 0.278431 0.317647 1" mesh="head_Link"/>
              <geom name="head_collision" class="collision" type="sphere" size="0.095" pos="0.016 0 0.25" rgba="1 0 0 1"/>
            </body>
            <body name="left_shoulder_pitch_Link" pos="0.0303 0.12 0.281524" quat="0.999048 0.0436194 0 0">
              <inertial pos="-0.00777149 0.080361 -9.251e-05" quat="0.764312 0.643184 0.0450315 0.0107214" mass="0.929224" diaginertia="0.00104564 0.000889743 0.000828335"/>
              <joint name="left_shoulder_pitch_joint" pos="0 0 0" axis="0 1 0" range="-2.87979 2.87979" actuatorfrcrange="-60 60" actuatorfrclimited="true" damping="1"/>
              <geom class="visual" type="mesh" rgba="0.2 0.2 0.2 1" mesh="left_shoulder_pitch_Link"/>
              <body name="left_shoulder_roll_Link" pos="0 0.0853247 0" quat="0.999048 -0.0436194 0 0">
                <inertial pos="0.00639561 0.0105654 -0.0936462" quat="0.98962 0.0440783 0.136717 -0.00425308" mass="0.870717" diaginertia="0.00226973 0.00219934 0.000618103"/>
                <joint name="left_shoulder_roll_joint" pos="0 0 0" axis="1 0 0" range="-0.0872665 2.61799" actuatorfrcrange="-60 60" actuatorfrclimited="true" damping="1"/>
                <geom class="visual" type="mesh" rgba="0.752941 0.752941 0.752941 1" mesh="left_shoulder_roll_Link"/>
                <geom name="left_shoulder_yaw_collision" class="collision" size="0.04 0.046" pos="0 0.01 -0.145" quat="1 0 0 0" type="capsule" rgba="1 0 0 1"/>
                <body name="left_shoulder_yaw_Link" pos="0 0.012 -0.148">
                  <inertial pos="0.0101335 -0.00110861 -0.0929565" quat="0.718367 -0.0709055 -0.0493976 0.690276" mass="0.774763" diaginertia="0.00169895 0.0016872 0.000474652"/>
                  <joint name="left_shoulder_yaw_joint" pos="0 0 0" axis="0 0 1" range="-2.79253 2.79253" actuatorfrcrange="-24 24" actuatorfrclimited="true" damping="1"/>
                  <geom class="visual" type="mesh" rgba="0.752941 0.752941 0.752941 1" mesh="left_shoulder_yaw_Link"/>
                  <body name="left_elbow_Link" pos="0.015 0 -0.117">
                    <inertial pos="0.0661462 -0.00160836 -0.0135604" quat="-0.0102217 0.747417 0.0913155 0.65797" mass="0.779854" diaginertia="0.00116455 0.0011239 0.000532406"/>
                    <joint name="left_elbow_joint" pos="0 0 0" axis="0 1 0" range="-1.0472 2.0944" actuatorfrcrange="-24 24" actuatorfrclimited="true" damping="1"/>
                    <geom class="visual" type="mesh" rgba="0.752941 0.752941 0.752941 1" mesh="left_elbow_Link"/>
                    <geom name="left_elbow_yaw_collision" class="collision" size="0.034 0.082" pos="0.08 0 -0.013" quat="0.707106781 0 0.707106781 0" type="capsule" rgba="1 0 0 1"/>
                    <body name="left_wrist_roll_Link" pos="0.113 0 -0.015">
                      <inertial pos="0.020843 -0.00070259 -4.661e-05" quat="0.340771 0.620094 -0.339066 0.619994" mass="0.190759" diaginertia="0.00016782 0.000138983 0.000126456"/>
                      <joint name="left_wrist_roll_joint" pos="0 0 0" axis="1 0 0" range="-2.79253 2.79253" actuatorfrcrange="-24 24" actuatorfrclimited="true" damping="1"/>
                      <geom class="visual" type="mesh" rgba="0.752941 0.752941 0.752941 1" mesh="left_wrist_roll_Link"/>
                      <body name="left_wrist_pitch_Link" pos="0.059 0 0">
                        <inertial pos="0.0230341 -0.00200561 -0.00197433" quat="-0.280734 0.696574 -0.245006 0.613144" mass="0.565609" diaginertia="0.000501153 0.000499059 0.000213928"/>
                        <joint name="left_wrist_pitch_joint" pos="0 0 0" axis="0 1 0" range="-1.62316 1.62316" actuatorfrcrange="-6 6" actuatorfrclimited="true" damping="1"/>
                        <geom class="visual" type="mesh" rgba="0.752941 0.752941 0.752941 1" mesh="left_wrist_pitch_Link"/>
                        <body name="left_wrist_yaw_Link" pos="0.046 0 0">
                          <inertial pos="0.0831948 0.00432942 0.00293438" quat="0.573609 0.39327 0.561777 0.448017" mass="0.26692" diaginertia="0.000847142 0.000725314 0.00022069"/>
                          <joint name="left_wrist_yaw_joint" pos="0 0 0" axis="0 0 1" range="-1.62316 1.62316" actuatorfrcrange="-6 6" actuatorfrclimited="true" damping="1"/>
                          <geom class="visual" type="mesh" rgba="0.752941 0.752941 0.752941 1" mesh="left_wrist_yaw_Link"/>
                          <geom class="visual" type="mesh" rgba="1 1 1 1" mesh="left_hand_fist_Link"/>
                          <geom name="left_hand_collision" class="collision" mesh="left_hand_fist_hull" />
                        </body>
                      </body>
                    </body>
                  </body>
                </body>
              </body>
            </body>
            <body name="right_shoulder_pitch_Link" pos="0.0303 -0.12 0.281524" quat="0.999048 -0.0436194 0 0">
              <inertial pos="-0.00777227 -0.0806353 -9.188e-05" quat="0.679084 0.731593 -0.0194448 -0.0568997" mass="0.929206" diaginertia="0.00104932 0.000890663 0.000828432"/>
              <joint name="right_shoulder_pitch_joint" pos="0 0 0" axis="0 1 0" range="-2.87979 2.87979" actuatorfrcrange="-60 60" actuatorfrclimited="true" damping="1"/>
              <geom class="visual" type="mesh" rgba="0.2 0.2 0.2 1" mesh="right_shoulder_pitch_Link"/>
              <body name="right_shoulder_roll_Link" pos="0 -0.0853247 0" quat="0.999048 0.0436194 0 0">
                <inertial pos="0.00644119 -0.010526 -0.0936448" quat="0.989613 -0.0439398 0.136753 0.00575584" mass="0.870733" diaginertia="0.00227049 0.00219832 0.000617382"/>
                <joint name="right_shoulder_roll_joint" pos="0 0 0" axis="1 0 0" range="-2.61799 0.0872665" actuatorfrcrange="-60 60" actuatorfrclimited="true" damping="1"/>
                <geom class="visual" type="mesh" rgba="0.752941 0.752941 0.752941 1" mesh="right_shoulder_roll_Link"/>
                <geom name="right_shoulder_yaw_collision" class="collision" size="0.04 0.046" pos="0 0.01 -0.145" quat="1 0 0 0" type="capsule" rgba="1 0 0 1"/>
                <body name="right_shoulder_yaw_Link" pos="0 -0.0119985 -0.147">
                  <inertial pos="0.0101248 0.00110631 -0.0939069" quat="0.672964 -0.0508689 -0.0700644 0.734591" mass="0.774761" diaginertia="0.00169694 0.00168631 0.000473428"/>
                  <joint name="right_shoulder_yaw_joint" pos="0 0 0" axis="0 0 1" range="-2.79253 2.79253" actuatorfrcrange="-24 24" actuatorfrclimited="true" damping="1"/>
                  <geom class="visual" type="mesh" rgba="0.752941 0.752941 0.752941 1" mesh="right_shoulder_yaw_Link"/>
                  <body name="right_elbow_Link" pos="0.015 0 -0.118">
                    <inertial pos="0.0661275 0.00152157 -0.0134656" quat="0.0100825 0.747961 -0.0906866 0.657441" mass="0.780928" diaginertia="0.0011655 0.00112334 0.000532229"/>
                    <joint name="right_elbow_joint" pos="0 0 0" axis="0 1 0" range="-1.0472 2.0944" actuatorfrcrange="-24 24" actuatorfrclimited="true" damping="1"/>
                    <geom class="visual" type="mesh" rgba="0.752941 0.752941 0.752941 1" mesh="right_elbow_Link"/>
                    <geom name="right_elbow_yaw_collision" class="collision" size="0.034 0.082" pos="0.08 0 -0.013" quat="0.707106781 0 0.707106781 0" type="capsule" rgba="1 0 0 1"/>
                    <body name="right_wrist_roll_Link" pos="0.113 0 -0.015">
                      <inertial pos="0.020843 0.00070259 4.661e-05" quat="0.619994 0.339066 -0.620094 0.340771" mass="0.190759" diaginertia="0.00016782 0.000138983 0.000126456"/>
                      <joint name="right_wrist_roll_joint" pos="0 0 0" axis="1 0 0" range="-2.79253 2.79253" actuatorfrcrange="-24 24" actuatorfrclimited="true" damping="1"/>
                      <geom class="visual" type="mesh" rgba="0.752941 0.752941 0.752941 1" mesh="right_wrist_roll_Link"/>
                      <body name="right_wrist_pitch_Link" pos="0.059 0 0">
                        <inertial pos="0.0230341 0.00200561 0.00197433" quat="-0.245006 0.613144 -0.280734 0.696574" mass="0.565609" diaginertia="0.000501153 0.000499059 0.000213928"/>
                        <joint name="right_wrist_pitch_joint" pos="0 0 0" axis="0 1 0" range="-1.62316 1.62316" actuatorfrcrange="-6 6" actuatorfrclimited="true" damping="1"/>
                        <geom class="visual" type="mesh" rgba="0.752941 0.752941 0.752941 1" mesh="right_wrist_pitch_Link"/>
                        <body name="right_wrist_yaw_Link" pos="0.046 0 0">
                          <inertial pos="0.0831948 0.00431716 0.00426838" quat="0.5594 0.405045 0.577531 0.435279" mass="0.26692" diaginertia="0.000844605 0.000723531 0.000219937"/>
                          <joint name="right_wrist_yaw_joint" pos="0 0 0" axis="0 0 1" range="-1.62316 1.62316" actuatorfrcrange="-6 6" actuatorfrclimited="true" damping="1"/>
                          <geom class="visual" type="mesh" rgba="0.752941 0.752941 0.752941 1" mesh="right_wrist_yaw_Link"/>
                          <geom class="visual" type="mesh" rgba="1 1 1 1" mesh="right_hand_fist_Link"/>
                          <geom name="right_hand_collision" class="collision" mesh="right_hand_fist_hull" />
                        </body>
                      </body>
                    </body>
                  </body>
                </body>
              </body>
            </body>
          </body>
        </body>
      </body>
    </body>
  </worldbody>

  <actuator>
    <motor name="left_hip_pitch_joint" joint="left_hip_pitch_joint"/>
    <motor name="left_hip_roll_joint" joint="left_hip_roll_joint"/>
    <motor name="left_hip_yaw_joint" joint="left_hip_yaw_joint"/>
    <motor name="left_knee_joint" joint="left_knee_joint"/>
    <!-- <motor name="left_ankle_pitch_joint" joint="left_ankle_pitch_joint"/>
    <motor name="left_ankle_roll_joint" joint="left_ankle_roll_joint"/> -->
    <motor name="left_ankle_pitch_joint" joint="left_ankle_motor_up_joint"/>
    <motor name="left_ankle_roll_joint" joint="left_ankle_motor_down_joint"/>

    <motor name="right_hip_pitch_joint" joint="right_hip_pitch_joint"/>
    <motor name="right_hip_roll_joint" joint="right_hip_roll_joint"/>
    <motor name="right_hip_yaw_joint" joint="right_hip_yaw_joint"/>
    <motor name="right_knee_joint" joint="right_knee_joint"/>
    <!-- <motor name="right_ankle_pitch_joint" joint="right_ankle_pitch_joint"/>
    <motor name="right_ankle_roll_joint" joint="right_ankle_roll_joint"/> -->
    <motor name="right_ankle_pitch_joint" joint="right_ankle_motor_up_joint"/>
    <motor name="right_ankle_roll_joint" joint="right_ankle_motor_down_joint"/>

    <motor name="waist_yaw_joint" joint="waist_yaw_joint"/>
    <!-- <motor name="waist_roll_joint" joint="waist_roll_joint"/>
    <motor name="waist_pitch_joint" joint="waist_pitch_joint"/> -->
    <motor name="waist_roll_joint" joint="left_waist_motor_joint"/>
    <motor name="waist_pitch_joint" joint="right_waist_motor_joint"/>

    <motor name="left_shoulder_pitch_joint" joint="left_shoulder_pitch_joint"/>
    <motor name="left_shoulder_roll_joint" joint="left_shoulder_roll_joint"/>
    <motor name="left_shoulder_yaw_joint" joint="left_shoulder_yaw_joint"/>
    <motor name="left_elbow_joint" joint="left_elbow_joint"/>
    <motor name="left_wrist_roll_joint" joint="left_wrist_roll_joint"/>
    <motor name="left_wrist_pitch_joint" joint="left_wrist_pitch_joint"/>
    <motor name="left_wrist_yaw_joint" joint="left_wrist_yaw_joint"/>

    <motor name="right_shoulder_pitch_joint" joint="right_shoulder_pitch_joint"/>
    <motor name="right_shoulder_roll_joint" joint="right_shoulder_roll_joint"/>
    <motor name="right_shoulder_yaw_joint" joint="right_shoulder_yaw_joint"/>
    <motor name="right_elbow_joint" joint="right_elbow_joint"/>
    <motor name="right_wrist_roll_joint" joint="right_wrist_roll_joint"/>
    <motor name="right_wrist_pitch_joint" joint="right_wrist_pitch_joint"/>
    <motor name="right_wrist_yaw_joint" joint="right_wrist_yaw_joint"/>
  </actuator>

  <sensor>
    <jointactuatorfrc name="jointactuatorfrc_left_hip_pitch_joint" joint="left_hip_pitch_joint"/> 
    <jointactuatorfrc name="jointactuatorfrc_left_hip_roll_joint" joint="left_hip_roll_joint"/> 
    <jointactuatorfrc name="jointactuatorfrc_left_hip_yaw_joint" joint="left_hip_yaw_joint"/> 
    <jointactuatorfrc name="jointactuatorfrc_left_knee_joint" joint="left_knee_joint"/> 
    <!-- <jointactuatorfrc name="jointactuatorfrc_left_ankle_pitch_joint" joint="left_ankle_pitch_joint"/> 
    <jointactuatorfrc name="jointactuatorfrc_left_ankle_roll_joint" joint="left_ankle_roll_joint"/>  -->
    <jointactuatorfrc name="jointactuatorfrc_left_ankle_pitch_joint" joint="left_ankle_motor_up_joint"/> 
    <jointactuatorfrc name="jointactuatorfrc_left_ankle_roll_joint" joint="left_ankle_motor_down_joint"/> 

    <jointactuatorfrc name="jointactuatorfrc_right_hip_pitch_joint" joint="right_hip_pitch_joint"/> 
    <jointactuatorfrc name="jointactuatorfrc_right_hip_roll_joint" joint="right_hip_roll_joint"/> 
    <jointactuatorfrc name="jointactuatorfrc_right_hip_yaw_joint" joint="right_hip_yaw_joint"/> 
    <jointactuatorfrc name="jointactuatorfrc_right_knee_joint" joint="right_knee_joint"/> 
    <!-- <jointactuatorfrc name="jointactuatorfrc_right_ankle_pitch_joint" joint="right_ankle_pitch_joint"/> 
    <jointactuatorfrc name="jointactuatorfrc_right_ankle_roll_joint" joint="right_ankle_roll_joint"/>  -->
    <jointactuatorfrc name="jointactuatorfrc_right_ankle_pitch_joint" joint="right_ankle_motor_up_joint"/> 
    <jointactuatorfrc name="jointactuatorfrc_right_ankle_roll_joint" joint="right_ankle_motor_down_joint"/> 

    <jointactuatorfrc name="jointactuatorfrc_waist_yaw_joint" joint="waist_yaw_joint"/>
    <!-- <jointactuatorfrc name="jointactuatorfrc_waist_roll_joint" joint="waist_roll_joint"/>
    <jointactuatorfrc name="jointactuatorfrc_waist_pitch_joint" joint="waist_pitch_joint"/> -->
    <jointactuatorfrc name="jointactuatorfrc_waist_roll_joint" joint="left_waist_motor_joint"/>
    <jointactuatorfrc name="jointactuatorfrc_waist_pitch_joint" joint="right_waist_motor_joint"/>

    <jointactuatorfrc name="jointactuatorfrc_left_shoulder_pitch_joint" joint="left_shoulder_pitch_joint"/> 
    <jointactuatorfrc name="jointactuatorfrc_left_shoulder_roll_joint" joint="left_shoulder_roll_joint"/> 
    <jointactuatorfrc name="jointactuatorfrc_left_shoulder_yaw_joint" joint="left_shoulder_yaw_joint"/> 
    <jointactuatorfrc name="jointactuatorfrc_left_elbow_joint" joint="left_elbow_joint"/> 
    <jointactuatorfrc name="jointactuatorfrc_left_wrist_roll_joint" joint="left_wrist_roll_joint"/> 
    <jointactuatorfrc name="jointactuatorfrc_left_wrist_pitch_joint" joint="left_wrist_pitch_joint"/> 
    <jointactuatorfrc name="jointactuatorfrc_left_wrist_yaw_joint" joint="left_wrist_yaw_joint"/> 

    <jointactuatorfrc name="jointactuatorfrc_right_shoulder_pitch_joint" joint="right_shoulder_pitch_joint"/> 
    <jointactuatorfrc name="jointactuatorfrc_right_shoulder_roll_joint" joint="right_shoulder_roll_joint"/> 
    <jointactuatorfrc name="jointactuatorfrc_right_shoulder_yaw_joint" joint="right_shoulder_yaw_joint"/> 
    <jointactuatorfrc name="jointactuatorfrc_right_elbow_joint" joint="right_elbow_joint"/> 
    <jointactuatorfrc name="jointactuatorfrc_right_wrist_roll_joint" joint="right_wrist_roll_joint"/> 
    <jointactuatorfrc name="jointactuatorfrc_right_wrist_pitch_joint" joint="right_wrist_pitch_joint"/> 
    <jointactuatorfrc name="jointactuatorfrc_right_wrist_yaw_joint" joint="right_wrist_yaw_joint"/>

    <jointpos name="jointpos_left_hip_pitch_joint" joint="left_hip_pitch_joint"/>
    <jointpos name="jointpos_left_hip_roll_joint" joint="left_hip_roll_joint"/>
    <jointpos name="jointpos_left_hip_yaw_joint" joint="left_hip_yaw_joint"/>
    <jointpos name="jointpos_left_knee_joint" joint="left_knee_joint"/>
    <!-- <jointpos name="jointpos_left_ankle_pitch_joint" joint="left_ankle_pitch_joint"/>
    <jointpos name="jointpos_left_ankle_roll_joint" joint="left_ankle_roll_joint"/> -->
    <jointpos name="jointpos_left_ankle_pitch_joint" joint="left_ankle_motor_up_joint"/>
    <jointpos name="jointpos_left_ankle_roll_joint" joint="left_ankle_motor_down_joint"/>

    <jointpos name="jointpos_right_hip_pitch_joint" joint="right_hip_pitch_joint"/>
    <jointpos name="jointpos_right_hip_roll_joint" joint="right_hip_roll_joint"/>
    <jointpos name="jointpos_right_hip_yaw_joint" joint="right_hip_yaw_joint"/>
    <jointpos name="jointpos_right_knee_joint" joint="right_knee_joint"/>
    <!-- <jointpos name="jointpos_right_ankle_pitch_joint" joint="right_ankle_pitch_joint"/>
    <jointpos name="jointpos_right_ankle_roll_joint" joint="right_ankle_roll_joint"/> -->
    <jointpos name="jointpos_right_ankle_pitch_joint" joint="right_ankle_motor_up_joint"/>
    <jointpos name="jointpos_right_ankle_roll_joint" joint="right_ankle_motor_down_joint"/>

    <jointpos name="jointpos_waist_yaw_joint" joint="waist_yaw_joint"/>
    <!-- <jointpos name="jointpos_waist_roll_joint" joint="waist_roll_joint"/>
    <jointpos name="jointpos_waist_pitch_joint" joint="waist_pitch_joint"/> -->
    <jointpos name="jointpos_waist_roll_joint" joint="left_waist_motor_joint"/>
    <jointpos name="jointpos_waist_pitch_joint" joint="right_waist_motor_joint"/>

    <jointpos name="jointpos_left_shoulder_pitch_joint" joint="left_shoulder_pitch_joint"/>
    <jointpos name="jointpos_left_shoulder_roll_joint" joint="left_shoulder_roll_joint"/>
    <jointpos name="jointpos_left_shoulder_yaw_joint" joint="left_shoulder_yaw_joint"/>
    <jointpos name="jointpos_left_elbow_joint" joint="left_elbow_joint"/>
    <jointpos name="jointpos_left_wrist_roll_joint" joint="left_wrist_roll_joint"/>
    <jointpos name="jointpos_left_wrist_pitch_joint" joint="left_wrist_pitch_joint"/>
    <jointpos name="jointpos_left_wrist_yaw_joint" joint="left_wrist_yaw_joint"/>

    <jointpos name="jointpos_right_shoulder_pitch_joint" joint="right_shoulder_pitch_joint"/>
    <jointpos name="jointpos_right_shoulder_roll_joint" joint="right_shoulder_roll_joint"/>
    <jointpos name="jointpos_right_shoulder_yaw_joint" joint="right_shoulder_yaw_joint"/>
    <jointpos name="jointpos_right_elbow_joint" joint="right_elbow_joint"/>
    <jointpos name="jointpos_right_wrist_roll_joint" joint="right_wrist_roll_joint"/>
    <jointpos name="jointpos_right_wrist_pitch_joint" joint="right_wrist_pitch_joint"/>
    <jointpos name="jointpos_right_wrist_yaw_joint" joint="right_wrist_yaw_joint"/>

    <jointvel name="jointvel_left_hip_pitch_joint" joint="left_hip_pitch_joint"/>
    <jointvel name="jointvel_left_hip_roll_joint" joint="left_hip_roll_joint"/>
    <jointvel name="jointvel_left_hip_yaw_joint" joint="left_hip_yaw_joint"/>
    <jointvel name="jointvel_left_knee_joint" joint="left_knee_joint"/>
    <!-- <jointvel name="jointvel_left_ankle_pitch_joint" joint="left_ankle_pitch_joint"/>
    <jointvel name="jointvel_left_ankle_roll_joint" joint="left_ankle_roll_joint"/> -->
    <jointvel name="jointvel_left_ankle_pitch_joint" joint="left_ankle_motor_up_joint"/>
    <jointvel name="jointvel_left_ankle_roll_joint" joint="left_ankle_motor_down_joint"/>

    <jointvel name="jointvel_right_hip_pitch_joint" joint="right_hip_pitch_joint"/>
    <jointvel name="jointvel_right_hip_roll_joint" joint="right_hip_roll_joint"/>
    <jointvel name="jointvel_right_hip_yaw_joint" joint="right_hip_yaw_joint"/>
    <jointvel name="jointvel_right_knee_joint" joint="right_knee_joint"/>
    <!-- <jointvel name="jointvel_right_ankle_pitch_joint" joint="right_ankle_pitch_joint"/> -->
    <!-- <jointvel name="jointvel_right_ankle_roll_joint" joint="right_ankle_roll_joint"/> -->
    <jointvel name="jointvel_right_ankle_pitch_joint" joint="right_ankle_motor_up_joint"/>
    <jointvel name="jointvel_right_ankle_roll_joint" joint="right_ankle_motor_down_joint"/>

    <jointvel name="jointvel_waist_yaw_joint" joint="waist_yaw_joint"/>
    <!-- <jointvel name="jointvel_waist_roll_joint" joint="waist_roll_joint"/>
    <jointvel name="jointvel_waist_pitch_joint" joint="waist_pitch_joint"/> -->
    <jointvel name="jointvel_waist_roll_joint" joint="left_waist_motor_joint"/>
    <jointvel name="jointvel_waist_pitch_joint" joint="right_waist_motor_joint"/>

    <jointvel name="jointvel_left_shoulder_pitch_joint" joint="left_shoulder_pitch_joint"/>
    <jointvel name="jointvel_left_shoulder_roll_joint" joint="left_shoulder_roll_joint"/>
    <jointvel name="jointvel_left_shoulder_yaw_joint" joint="left_shoulder_yaw_joint"/>
    <jointvel name="jointvel_left_elbow_joint" joint="left_elbow_joint"/>
    <jointvel name="jointvel_left_wrist_roll_joint" joint="left_wrist_roll_joint"/>
    <jointvel name="jointvel_left_wrist_pitch_joint" joint="left_wrist_pitch_joint"/>
    <jointvel name="jointvel_left_wrist_yaw_joint" joint="left_wrist_yaw_joint"/>

    <jointvel name="jointvel_right_shoulder_pitch_joint" joint="right_shoulder_pitch_joint"/>
    <jointvel name="jointvel_right_shoulder_roll_joint" joint="right_shoulder_roll_joint"/>
    <jointvel name="jointvel_right_shoulder_yaw_joint" joint="right_shoulder_yaw_joint"/>
    <jointvel name="jointvel_right_elbow_joint" joint="right_elbow_joint"/>
    <jointvel name="jointvel_right_wrist_roll_joint" joint="right_wrist_roll_joint"/>
    <jointvel name="jointvel_right_wrist_pitch_joint" joint="right_wrist_pitch_joint"/>
    <jointvel name="jointvel_right_wrist_yaw_joint" joint="right_wrist_yaw_joint"/>

    <force name="left_foot_force" site="left_foot"/>
    <torque name="left_foot_torque" site="left_foot"/>

    <force name="right_foot_force" site="right_foot"/>
    <torque name="right_foot_torque" site="right_foot"/>

    <framequat name="body-orientation" objtype="site" objname="imu_in_pelvis" noise="0" />
    <gyro name="body-angular-velocity" site="imu_in_pelvis" noise="0.001" />
    <framepos name="body-linear-pos" objtype="site" objname="imu_in_pelvis" />
    <velocimeter name="body-linear-vel" site="imu_in_pelvis" />
    <accelerometer name="body-linear-acceleration" site="imu_in_pelvis" noise="0.001" />

    <framequat name="torso-orientation" objtype="site" objname="imu_in_torso" noise="0" />
    <gyro name="torso-angular-velocity" site="imu_in_torso" noise="0.001" />
    <framepos name="torso-linear-pos" objtype="site" objname="imu_in_torso" />
    <velocimeter name="torso-linear-vel" site="imu_in_torso" />
    <accelerometer name="torso-linear-acceleration" site="imu_in_torso" noise="0.001" />

    <subtreeangmom name="root_angmom" body="pelvis_link"/>
  </sensor>

  <contact>
    <exclude body1="left_elbow_Link" body2="left_wrist_pitch_Link"/>
    <exclude body1="right_elbow_Link" body2="right_wrist_pitch_Link"/>
    <exclude body1="pelvis_link" body2="right_hip_roll_Link"/>
    <exclude body1="pelvis_link" body2="left_hip_roll_Link"/>
    <exclude body1="pelvis_link" body2="right_hip_pitch_Link"/>
    <exclude body1="pelvis_link" body2="left_hip_pitch_Link"/>
  </contact>

  <equality>
    <connect name = 'left_ankle_long_loop' body1 = 'left_ankle_rod_long_up_Link' body2 = 'left_ankle_roll_Link' solimp = '0.9999 0.9999 0.001 0.5 2' anchor = '0.00200000000011402 0.0124412641467721 -0.292728910335877' />
    <connect name = 'left_ankle_short_loop' body1 = 'left_ankle_rod_short_up_Link' body2 = 'left_ankle_roll_Link' solimp = '0.9999 0.9999 0.001 0.5 2' anchor = '-0.0059999999998874 -0.0124750976533259 -0.207538844408803' />
    <connect name = 'right_ankle_long_loop' body1 = 'right_ankle_rod_long_up_Link' body2 = 'right_ankle_roll_Link' solimp = '0.9999 0.9999 0.001 0.5 2' anchor = '0.00200000000011402 -0.0124412641467721 -0.292728910335877' />
    <connect name = 'right_ankle_short_loop' body1 = 'right_ankle_rod_short_up_Link' body2 = 'right_ankle_roll_Link' solimp = '0.9999 0.9999 0.001 0.5 2' anchor = '-0.0059999999998874 0.0124750976533259 -0.207538844408803' />

    <connect name = 'left_waist_loop' body1 = 'left_waist_rod_up_Link' body2 = 'waist_yaw_Link' solimp = '0.9999 0.9999 0.001 0.5 2' anchor = '0.0052 0.00345955 -0.0967987' />
    <connect name = 'right_waist_loop' body1 = 'right_waist_rod_up_Link' body2 = 'waist_yaw_Link' solimp = '0.9999 0.9999 0.001 0.5 2' anchor = '0.0052 -0.00345955 -0.0967987' />
  </equality>
  <keyframe>
    <key name="home_default" qpos='-0.0703236 -6.13306e-05 1.08763 0.999996 2.09159e-05 -5.1077e-05 -0.00270636 -0.130857 0.00700989 -0.0350348 0.251921 -0.125541 -0.00917856 -0.137932 0.997689 -0.0679497 0.000248708 -0.000479953 0.149548 0.997294 0.0734842 0.000272868 -0.00198032 -0.130853 -0.0070586 0.0350569 0.251951 -0.125558 0.00913733 0.137975 0.99662 0.0682035 0.00142999 -0.0457607 -0.149541 0.996187 -0.0720196 0.000913849 0.0492301 4.2157e-08 0.000430893 0.00944988 -0.0125461 0.99998 0.00600919 -0.00103903 0.00178083 0.0130173 0.999978 -0.0063055 -0.00103899 -0.00178839 -0.00665655 0.2953 0.112997 -0.00213683 0.804646 -2.86016e-07 0.00402472 -0.000685013 0.295408 -0.113148 0.00207669 0.80476 -0.000127378 0.00447275 0.000279328'/>
  </keyframe>
</mujoco>
