<mujoco model="0000012082_A3T2-URDF布局.SLDASM">
  <compiler angle="radian" meshdir="../meshes" autolimits="true"/>
  <option timestep="0.001"/>

  <visual>
    <global azimuth="150" elevation="-20"/>
    <headlight ambient="0.3 0.3 0.3" diffuse="0.6 0.6 0.6" specular="0 0 0"/>
    <scale forcewidth="0.03" contactwidth="0.01" contactheight="0.02" com="1" framelength="0.6" framewidth="0.05"/>
    <rgba haze="0.15 0.25 0.35 1" com="0.502 1 0 0.5" contactpoint="1 1 0.6 0.4" contactforce="0.98 0.4 0.4 1"/>
  </visual>

  <statistic extent="1.1" center="0 0 0.55"/>

  <default>
    <geom contype="0" conaffinity="0" friction="1 1" solref="0.005"/>
    <default class="visual">
      <geom group="2" type="mesh" density="0" contype="0" conaffinity="0"/>
    </default>
    <equality solref="0.005"/>
    <default class="zhiyuan"/>
    <default class="collision">
      <geom type="capsule" contype="1" group="3"/>
      <default class="collision-left">
        <geom contype="2" conaffinity="4"/>
      </default>
      <default class="collision-right">
        <geom contype="4" conaffinity="2"/>
      </default>
    </default>
  </default>

  <asset>
    <!-- <texture type="skybox" name="skybox" builtin="gradient" mark="random" rgb1="0.2 0.3 0.4" rgb2="0 0 0" markrgb="1 1 1" random="0.001" width="1000" height="6000"/> -->
    <!-- <texture type="2d" name="groundplane" builtin="checker" mark="edge" rgb1="0.2 0.3 0.4" rgb2="0.1 0.2 0.3" markrgb="0.8 0.8 0.8" width="1000" height="1000"/> -->
    <material name="metalic silver" rgba="0.59 0.59 0.65 1"/>
    <material name="metalic black" rgba="0.235294 0.235294 0.235294 1"/>
    <!-- <material name="groundplane" texture="groundplane" texuniform="true" texrepeat="5 5" reflectance="0.2"/> -->

    <mesh name="pelvis_link" content_type="model/stl" file="pelvis_link.STL"/>
    <mesh name="waist_yaw_Link" content_type="model/stl" file="waist_yaw_Link.STL"/>
    <mesh name="waist_roll_Link" content_type="model/stl" file="waist_roll_Link.STL"/>
    <mesh name="torso_Link" content_type="model/stl" file="torso_Link.STL"/>
    <mesh name="torso_shell_Link" content_type="model/stl" file="torso_shell_Link.STL"/>
    <mesh name="imu_in_torso_Link" content_type="model/stl" file="imu_in_torso_Link.STL"/>
    <mesh name="head_yaw_Link" content_type="model/stl" file="head_yaw_Link.STL"/>
    <mesh name="left_shoulder_pitch_Link" content_type="model/stl" file="left_shoulder_pitch_Link.STL"/>
    <mesh name="left_shoulder_roll_Link" content_type="model/stl" file="left_shoulder_roll_Link.STL"/>
    <mesh name="left_shoulder_yaw_Link" content_type="model/stl" file="left_shoulder_yaw_Link.STL"/>
    <mesh name="left_elbow_Link" content_type="model/stl" file="left_elbow_Link.STL"/>
    <mesh name="left_wrist_roll_Link" content_type="model/stl" file="left_wrist_roll_Link.STL"/>
    <mesh name="left_wrist_pitch_Link" content_type="model/stl" file="left_wrist_pitch_Link.STL"/>
    <mesh name="left_wrist_yaw_Link" content_type="model/stl" file="left_wrist_yaw_Link.STL"/>
    <mesh name="left_hand_palm_Link" content_type="model/stl" file="left_hand_palm_Link.STL"/>
    <mesh name="right_shoulder_pitch_Link" content_type="model/stl" file="right_shoulder_pitch_Link.STL"/>
    <mesh name="right_shoulder_roll_Link" content_type="model/stl" file="right_shoulder_roll_Link.STL"/>
    <mesh name="right_shoulder_yaw_Link" content_type="model/stl" file="right_shoulder_yaw_Link.STL"/>
    <mesh name="right_elbow_Link" content_type="model/stl" file="right_elbow_Link.STL"/>
    <mesh name="right_wrist_roll_Link" content_type="model/stl" file="right_wrist_roll_Link.STL"/>
    <mesh name="right_wrist_pitch_Link" content_type="model/stl" file="right_wrist_pitch_Link.STL"/>
    <mesh name="right_wrist_yaw_Link" content_type="model/stl" file="right_wrist_yaw_Link.STL"/>
    <mesh name="right_hand_palm_Link" content_type="model/stl" file="right_hand_palm_Link.STL"/>
    <mesh name="imu_in_pelvis_Link" content_type="model/stl" file="imu_in_pelvis_Link.STL"/>
    <mesh name="left_hip_pitch_Link" content_type="model/stl" file="left_hip_pitch_Link.STL"/>
    <mesh name="left_hip_roll_Link" content_type="model/stl" file="left_hip_roll_Link.STL"/>
    <mesh name="left_hip_yaw_Link" content_type="model/stl" file="left_hip_yaw_Link.STL"/>
    <mesh name="left_knee_Link" content_type="model/stl" file="left_knee_Link.STL"/>
    <mesh name="left_knee_shell_Link" content_type="model/stl" file="left_knee_shell_Link.STL"/>
    <mesh name="left_ankle_pitch_Link" content_type="model/stl" file="left_ankle_pitch_Link.STL"/>
    <mesh name="left_ankle_roll_Link" content_type="model/stl" file="left_ankle_roll_Link.STL"/>
    <mesh name="right_hip_pitch_Link" content_type="model/stl" file="right_hip_pitch_Link.STL"/>
    <mesh name="right_hip_roll_Link" content_type="model/stl" file="right_hip_roll_Link.STL"/>
    <mesh name="right_hip_yaw_Link" content_type="model/stl" file="right_hip_yaw_Link.STL"/>
    <mesh name="right_knee_Link" content_type="model/stl" file="right_knee_Link.STL"/>
    <mesh name="right_knee_shell_Link" content_type="model/stl" file="right_knee_shell_Link.STL"/>
    <mesh name="right_ankle_pitch_Link" content_type="model/stl" file="right_ankle_pitch_Link.STL"/>
    <mesh name="right_ankle_roll_Link" content_type="model/stl" file="right_ankle_roll_Link.STL"/>
  </asset>

  <worldbody>
    <!-- <geom name="floor" size="300 300 0.125" type="plane" conaffinity="7" material="groundplane"/> -->
    <!-- <light pos="0 0 10" dir="0 0 -1" directional="true"/> -->
    <!-- <light name="spotlight" target="pelvis_link" pos="0 -1 2" dir="0 0 -1" mode="targetbodycom"/> -->
    <body name="pelvis_link" pos="0 0 1.1">
      <!-- <light pos="0 0 2" mode="trackcom"/> -->
      <!-- <camera name="tracking" pos="1.734 -1.135 0.35" xyaxes="0.552 0.834 -0.000 -0.170 0.112 0.979" mode="trackcom"/> -->
      <inertial pos="-0.00124899 3.059e-05 -0.12701365" quat="0.997276 0.0734874 0.00605114 -0.0019108" mass="4.98224861" diaginertia="0.0246338 0.0181068 0.0155254"/>
      <!-- <joint name="floating_joint" type="free" range="-2.61799 2.61799" actuatorfrcrange="-220 220" actuatorfrclimited="true"/> -->
      <joint name="floating_joint" type="free" />
      <geom class="visual" type="mesh" rgba="0.101961 0.101961 0.101961 1" mesh="pelvis_link"/>
      <geom name="pelvis_collision" class="collision" size="0.07 0.046" pos="0 0 -0.15" quat="0.707106781 0.707106781 0 0" type="capsule" rgba="1 0 0 1"/>
      <site name="imu_in_pelvis" size="0.01" pos="-0.00287 0 -0.21015"/>
      <!-- <geom pos="0.00437 0 -0.21165" quat="1 0 0 0" type="mesh" rgba="0.1 0.1 0.1 1" mesh="imu_in_pelvis_Link"/> -->
      <body name="left_hip_pitch_Link" pos="0 0.12298 -0.17875" quat="0.991445 -0.130526 0 0">
        <inertial pos="0.00721133 0.00458584 -0.0364447" quat="0.955376 0.291453 -0.029975 -0.0376015" mass="1.87346" diaginertia="0.00360407 0.00305967 0.0020625"/>
        <joint name="left_hip_pitch_joint" pos="0 0 0" axis="0 1 0" range="-2.51327 2.93215" actuatorfrcrange="-220 220" actuatorfrclimited="true" damping="1"/>
        <geom class="visual" type="mesh" rgba="0.1 0.1 0.1 1" mesh="left_hip_pitch_Link"/>
        <body name="left_hip_roll_Link" pos="0 0.011316 -0.042233" quat="0.991445 0.130526 0 0">
          <inertial pos="-0.00491752 0.00270388 -0.029806" quat="0.505262 0.485974 0.488526 0.519502" mass="0.74493" diaginertia="0.00258919 0.00219627 0.00173352"/>
          <joint name="left_hip_roll_joint" pos="0 0 0" axis="1 0 0" range="-0.523599 1.48353" actuatorfrcrange="-220 220" actuatorfrclimited="true" damping="1"/>
          <geom class="visual" type="mesh" rgba="1 1 1 1" mesh="left_hip_roll_Link"/>
          <geom name="left_hip_collision" class="collision" size="0.046" pos="-0.018 -0.015 -0.01" type="sphere" rgba="1 0 0 1"/>
          <body name="left_hip_yaw_Link">
            <inertial pos="0.00514402 -0.00057695 -0.175518" quat="0.998587 -0.0068251 -0.0293093 -0.0438022" mass="2.64563" diaginertia="0.0304781 0.0300243 0.00574584"/>
            <joint name="left_hip_yaw_joint" pos="0 0 0" axis="0 0 1" range="-2.72271 2.72271" actuatorfrcrange="-220 220" actuatorfrclimited="true" damping="1"/>
            <geom class="visual" type="mesh" rgba="1 1 1 1" mesh="left_hip_yaw_Link"/>
            <geom name="left_thigh_collision" class="collision" size="0.054 0.07" pos="0.0065 0.0 -0.19" type="capsule" rgba="1 0 0 1"/>
            <body name="left_knee_Link" pos="0 0 -0.37">
              <inertial pos="0.00089998 -0.0008566 -0.116035" quat="0.674731 0.0135554 0.00734208 0.737903" mass="5.23624" diaginertia="0.0887092 0.0870746 0.00794668"/>
              <joint name="left_knee_joint" pos="0 0 0" axis="0 1 0" range="-0.122173 2.53073" actuatorfrcrange="-320 320" actuatorfrclimited="true" damping="1.5"/>
              <geom class="visual" type="mesh" rgba="1 1 1 1" mesh="left_knee_Link"/>
              <geom class="visual" type="mesh" rgba="1 1 1 1" mesh="left_knee_shell_Link"/>
              <geom name="left_shin_collision" class="collision" size="0.057 0.1" pos="0.0 0.0 -0.22" type="capsule" rgba="1 0 0 1"/>
              <body name="left_ankle_pitch_Link" pos="0 0 -0.415">
                <inertial pos="0.00315163 0 0.00019267" quat="0.501079 0.501079 -0.498918 0.498918" mass="0.101008" diaginertia="3.69603e-05 2.30797e-05 1.751e-05"/>
                <joint name="left_ankle_pitch_joint" pos="0 0 0" axis="0 1 0" range="-0.907571 0.523599" actuatorfrcrange="-115 115" actuatorfrclimited="true" damping="3"/>
                <geom class="visual" type="mesh" rgba="1 1 1 1" mesh="left_ankle_pitch_Link"/>
                <body name="left_ankle_roll_Link">
                  <inertial pos="0.0282287 0 -0.0485267" quat="-1.95727e-05 0.737287 -7.7642e-06 0.67558" mass="0.82545" diaginertia="0.00418238 0.00404434 0.00079071"/>
                  <joint name="left_ankle_roll_joint" pos="0 0 0" axis="1 0 0" range="-0.349066 0.349066" actuatorfrcrange="-54 54" actuatorfrclimited="true" damping="3"/>
                  <geom class="visual" type="mesh" rgba="0.1 0.1 0.1 1" mesh="left_ankle_roll_Link"/>
                  <site name="left_foot" rgba="1 0 0 1" pos="0.04 0 -0.067"/>
                  <geom name="left_foot1_collision" class="collision" size="0.002" pos="0.185 0 -0.053" type="sphere"/>
                  <geom name="left_foot2_collision" class="collision" size="0.002" pos="-0.084 0 -0.067" type="sphere"/>
                  <geom name="left_foot3_collision" class="collision" size="0.002" pos="0.145 0.044 -0.065" type="sphere"/>
                  <geom name="left_foot4_collision" class="collision" size="0.002" pos="0.145 -0.044 -0.065" type="sphere"/>
                  <geom name="left_foot5_collision" class="collision" size="0.002" pos="0.065 0.051 -0.067" type="sphere"/>
                  <geom name="left_foot6_collision" class="collision" size="0.002" pos="0.065 -0.051 -0.067" type="sphere"/>
                  <geom name="left_foot7_collision" class="collision" size="0.002" pos="-0.037 0.036 -0.067" type="sphere"/>
                  <geom name="left_foot8_collision" class="collision" size="0.002" pos="-0.037 -0.036 -0.067" type="sphere"/>
                  <geom name="left_foot9_collision" class="collision" size="0.002" pos="0.105 0.051 -0.067" type="sphere"/>
                  <geom name="left_foot10_collision" class="collision" size="0.002" pos="0.105 -0.051 -0.067" type="sphere"/>
                  <geom name="left_foot11_collision" class="collision" size="0.002" pos="0.04 0 -0.067" type="sphere"/>
                  <geom name="left_foot12_collision" class="collision" size="0.002" pos="0 -0.033 -0.065" type="sphere"/>
                  <geom name="left_foot13_collision" class="collision" size="0.002" pos="0 0.033 -0.065" type="sphere"/>
                </body>
              </body>
            </body>
          </body>
        </body>
      </body>
      <body name="right_hip_pitch_Link" pos="0 -0.12298 -0.17875" quat="0.991445 0.130526 0 0">
        <inertial pos="0.00721166 -0.00459403 -0.0364441" quat="0.9553 -0.291636 -0.029918 0.0381367" mass="1.87346" diaginertia="0.0036045 0.00306023 0.00206222"/>
        <joint name="right_hip_pitch_joint" pos="0 0 0" axis="0 1 0" range="-2.51327 2.93215" actuatorfrcrange="-220 220" actuatorfrclimited="true" damping="1"/>
        <geom class="visual" type="mesh" rgba="0.1 0.1 0.1 1" mesh="right_hip_pitch_Link"/>
        <body name="right_hip_roll_Link" pos="-0.0011 -0.011316 -0.042233" quat="0.991445 -0.130526 0 0">
          <inertial pos="-0.00490292 -0.00270519 -0.0298049" quat="0.519314 0.488716 0.486197 0.505056" mass="0.744914" diaginertia="0.00258927 0.0021963 0.0017335"/>
          <joint name="right_hip_roll_joint" pos="0 0 0" axis="1 0 0" range="-1.48353 0.523599" actuatorfrcrange="-220 220" actuatorfrclimited="true" damping="1"/>
          <geom class="visual" type="mesh" rgba="1 1 1 1" mesh="right_hip_roll_Link"/>
          <geom name="right_hip_collision" class="collision" size="0.046" pos="-0.018 0.015 -0.01" type="sphere" rgba="1 0 0 1"/>
          <body name="right_hip_yaw_Link">
            <inertial pos="0.00514477 0.00058875 -0.175434" quat="0.998764 0.00685475 -0.029176 0.0396637" mass="2.64888" diaginertia="0.0304909 0.0300338 0.00575075"/>
            <joint name="right_hip_yaw_joint" pos="0 0 0" axis="0 0 1" range="-2.72271 2.72271" actuatorfrcrange="-220 220" actuatorfrclimited="true" damping="1"/>
            <geom class="visual" type="mesh" rgba="1 1 1 1" mesh="right_hip_yaw_Link"/>
            <geom name="right_thigh_collision" class="collision" size="0.054 0.07" pos="0.0065 0.0 -0.19" type="capsule" rgba="1 0 0 1"/>
            <body name="right_knee_Link" pos="0 0 -0.37">
              <inertial pos="0.00135435 0.00032516 -0.117896" quat="0.711055 0.00357072 0.0146974 0.702973" mass="5.23155" diaginertia="0.0931634 0.0916264 0.00776674"/>
              <joint name="right_knee_joint" pos="0 0 0" axis="0 1 0" range="-0.122173 2.53073" actuatorfrcrange="-320 320" actuatorfrclimited="true" damping="1.5"/>
              <geom class="visual" type="mesh" rgba="1 1 1 1" mesh="right_knee_Link"/>
              <geom class="visual" type="mesh" rgba="1 1 1 1" mesh="right_knee_shell_Link"/>
              <geom name="right_shin_collision" class="collision" size="0.057 0.1" pos="0.0 0.0 -0.22" type="capsule" rgba="1 0 0 1"/>
              <body name="right_ankle_pitch_Link" pos="0 0 -0.415">
                <inertial pos="0.00315163 0 0.00019267" quat="0.501079 0.501079 -0.498918 0.498918" mass="0.101008" diaginertia="3.69603e-05 2.30797e-05 1.751e-05"/>
                <joint name="right_ankle_pitch_joint" pos="0 0 0" axis="0 1 0" range="-0.907571 0.523599" actuatorfrcrange="-115 115" actuatorfrclimited="true" damping="3"/>
                <geom class="visual" type="mesh" rgba="1 1 1 1" mesh="right_ankle_pitch_Link"/>
                <body name="right_ankle_roll_Link">
                  <inertial pos="0.0282287 1.2e-06 -0.0485259" quat="-4.38594e-05 0.737287 -3.44675e-05 0.67558" mass="0.82545" diaginertia="0.0041824 0.00404439 0.00079077"/>
                  <joint name="right_ankle_roll_joint" pos="0 0 0" axis="1 0 0" range="-0.349066 0.349066" actuatorfrcrange="-54 54" actuatorfrclimited="true" damping="3"/>
                  <geom class="visual" type="mesh" rgba="0.1 0.1 0.1 1" mesh="right_ankle_roll_Link"/>
                  <site name="right_foot" rgba="1 0 0 1" pos="0.04 0 -0.067"/>
                  <geom name="right_foot1_collision" class="collision" size="0.002" pos="0.185 0 -0.053" type="sphere"/>
                  <geom name="right_foot2_collision" class="collision" size="0.002" pos="-0.084 0 -0.067" type="sphere"/>
                  <geom name="right_foot3_collision" class="collision" size="0.002" pos="0.145 0.044 -0.065" type="sphere"/>
                  <geom name="right_foot4_collision" class="collision" size="0.002" pos="0.145 -0.044 -0.065" type="sphere"/>
                  <geom name="right_foot5_collision" class="collision" size="0.002" pos="0.065 0.051 -0.067" type="sphere"/>
                  <geom name="right_foot6_collision" class="collision" size="0.002" pos="0.065 -0.051 -0.067" type="sphere"/>
                  <geom name="right_foot7_collision" class="collision" size="0.002" pos="-0.037 0.036 -0.067" type="sphere"/>
                  <geom name="right_foot8_collision" class="collision" size="0.002" pos="-0.037 -0.036 -0.067" type="sphere"/>
                  <geom name="right_foot9_collision" class="collision" size="0.002" pos="0.105 0.051 -0.067" type="sphere"/>
                  <geom name="right_foot10_collision" class="collision" size="0.002" pos="0.105 -0.051 -0.067" type="sphere"/>
                  <geom name="right_foot11_collision" class="collision" size="0.002" pos="0.04 0 -0.067" type="sphere"/>
                  <geom name="right_foot12_collision" class="collision" size="0.002" pos="0 -0.033 -0.065" type="sphere"/>
                  <geom name="right_foot13_collision" class="collision" size="0.002" pos="0 0.033 -0.065" type="sphere"/>
                </body>
              </body>
            </body>
          </body>
        </body>
      </body>

      <body name="waist_yaw_Link">
        <inertial pos="0.0018168 -0.00204337 -0.0228619" quat="0.056891 0.725998 -0.0393199 0.68421" mass="0.245194" diaginertia="0.000360867 0.000232085 0.000183698"/>
        <joint name="waist_yaw_joint" pos="0 0 0" axis="0 0 1" range="-2.61799 2.61799" actuatorfrcrange="-220 220" actuatorfrclimited="true" damping="1"/>
        <geom class="visual" type="mesh" rgba="0.1 0.1 0.1 1" mesh="waist_yaw_Link"/>
        <body name="waist_roll_Link">
          <inertial pos="-0.02 0 0.0024982" quat="0 0.707107 0 0.707107" mass="0.135382" diaginertia="4.8e-05 2.953e-05 2.952e-05"/>
          <joint name="waist_roll_joint" pos="0 0 0" axis="1 0 0" range="-0.349066 0.349066" actuatorfrcrange="-46 46" actuatorfrclimited="true" damping="1.5"/>
          <geom class="visual" type="mesh" rgba="0.1 0.1 0.1 1" mesh="waist_roll_Link"/>
          <body name="torso_Link" pos="-0.02 0 0.005">
            <inertial pos="0.0208457 -0.000198063 0.195589" quat="0.999744 0.0053016 -0.0182721 -0.0122079" mass="17.4968" diaginertia="0.219593 0.174826 0.117957"/>
            <joint name="waist_pitch_joint" pos="0 0 0" axis="0 1 0" range="-0.488692 0.418879" actuatorfrcrange="-118 118" actuatorfrclimited="true" damping="1.5"/>
            <geom class="visual" type="mesh" rgba="0.1 0.1 0.1 1" mesh="torso_Link"/>
            <geom class="visual" type="mesh" rgba="1 1 1 1" mesh="torso_shell_Link"/>
            <!-- <geom pos="0 0 0.11185" quat="1 0 0 0" type="mesh" rgba="0.1 0.1 0.1 1" mesh="imu_in_torso_Link"/> -->
            <geom name="torso_collision" class="collision" type="mesh" mesh="torso_Link"/>
            <site name="imu_in_torso" size="0.01" pos="0 0 0.11185"/>
            <body name="head_yaw_Link" pos="0.0303 0 0.28896">
              <inertial pos="0.0127877 -4.087e-05 0.256941" quat="0.703983 -0.0930803 -0.0952547 0.697618" mass="2.1" diaginertia="0.0136654 0.0127025 0.00728517"/>
              <joint name="head_yaw_joint" pos="0 0 0" axis="0 0 1" range="-0.785398 0.785398" actuatorfrcrange="-6 6" actuatorfrclimited="true" damping="1"/>
              <geom class="visual" type="mesh" rgba="0.1 0.1 0.1 1" mesh="head_yaw_Link"/>
              <geom name="head_collision" class="collision" type="sphere" size="0.095" pos="0.016 0 0.25" rgba="1 0 0 1"/>
            </body>
            <body name="left_shoulder_pitch_Link" pos="0.0303 0.14822 0.28382" quat="0.999048 0.0436192 0 0">
              <inertial pos="0.00096906 0.0547743 0.00016529" quat="0.721275 0.692333 0.0172613 0.0117828" mass="1.01945" diaginertia="0.00117978 0.000989191 0.000956331"/>
              <joint name="left_shoulder_pitch_joint" pos="0 0 0" axis="0 1 0" range="-2.87979 2.87979" actuatorfrcrange="-60 60" actuatorfrclimited="true" damping="1"/>
              <geom class="visual" type="mesh" rgba="0.1 0.1 0.1 1" mesh="left_shoulder_pitch_Link"/>
              <body name="left_shoulder_roll_Link" pos="0 0.059 0">
                <inertial pos="0.00085399 0.00181228 -0.0872244" quat="0.712516 0.0219877 0.0452494 0.69985" mass="0.958548" diaginertia="0.00273763 0.00244948 0.0012518"/>
                <joint name="left_shoulder_roll_joint" pos="0 0 0" axis="1 0 0" range="-0.0872665 2.61799" actuatorfrcrange="-60 60" actuatorfrclimited="true" damping="1"/>
                <geom class="visual" type="mesh" rgba="1 1 1 1" mesh="left_shoulder_roll_Link"/>
                <geom name="left_shoulder_yaw_collision" class="collision" size="0.04 0.046" pos="0 0.01 -0.145" quat="1 0 0 0" type="capsule" rgba="1 0 0 1"/>
                <body name="left_shoulder_yaw_Link" pos="0 -0.0028935 -0.14781" quat="0.999048 -0.0436192 0 0">
                  <inertial pos="0.00426502 -0.00144977 -0.0890828" quat="0.713571 -0.043208 -0.0266623 0.698741" mass="0.999559" diaginertia="0.00331014 0.00326462 0.000848276"/>
                  <joint name="left_shoulder_yaw_joint" pos="0 0 0" axis="0 0 1" range="-2.79253 2.79253" actuatorfrcrange="-24 24" actuatorfrclimited="true" damping="1"/>
                  <geom class="visual" type="mesh" rgba="1 1 1 1" mesh="left_shoulder_yaw_Link"/>
                  <body name="left_elbow_Link" pos="0.01 0 -0.1325">
                    <inertial pos="0.0776011 -0.00121006 -0.0104096" quat="-0.0210142 0.709386 0.0505757 0.702689" mass="0.712044" diaginertia="0.00124115 0.00117025 0.000537076"/>
                    <joint name="left_elbow_joint" pos="0 0 0" axis="0 1 0" range="-0.959931 1.74533" actuatorfrcrange="-24 24" actuatorfrclimited="true" damping="1"/>
                    <geom class="visual" type="mesh" rgba="1 1 1 1" mesh="left_elbow_Link"/>
                    <geom name="left_elbow_yaw_collision" class="collision" size="0.034 0.082" pos="0.08 0 -0.013" quat="0.707106781 0 0.707106781 0" type="capsule" rgba="1 0 0 1"/>
                    <body name="left_wrist_roll_Link" pos="0.129 0 -0.01">
                      <inertial pos="0.0209014 -0.00032839 1.007e-05" quat="0.286321 0.645908 -0.288116 0.646384" mass="0.19186" diaginertia="0.00019562 0.000163226 0.000151184"/>
                      <joint name="left_wrist_roll_joint" pos="0 0 0" axis="1 0 0" range="-2.79253 2.79253" actuatorfrcrange="-24 24" actuatorfrclimited="true" damping="1"/>
                      <geom class="visual" type="mesh" rgba="1 1 1 1" mesh="left_wrist_roll_Link"/>
                      <body name="left_wrist_pitch_Link" pos="0.06 0 0">
                        <inertial pos="0.022825 -0.00080274 -0.0007711" quat="0.486247 0.495615 0.521419 0.496037" mass="0.567464" diaginertia="0.000515892 0.000514735 0.000233443"/>
                        <joint name="left_wrist_pitch_joint" pos="0 0 0" axis="0 1 0" range="-1.62316 1.62316" actuatorfrcrange="-6 6" actuatorfrclimited="true" damping="1"/>
                        <geom class="visual" type="mesh" rgba="0.1 0.1 0.1 1" mesh="left_wrist_pitch_Link"/>
                        <body name="left_wrist_yaw_Link" pos="0.046 0 0">
                          <inertial pos="0.0967447 -0.00348459 0.00378925" quat="0.43101 0.573575 0.385996 0.57987" mass="0.539323" diaginertia="0.00158567 0.00134801 0.00042374"/>
                          <joint name="left_wrist_yaw_joint" pos="0 0 0" axis="0 0 1" range="-1.62316 1.62316" actuatorfrcrange="-6 6" actuatorfrclimited="true" damping="1"/>
                          <geom class="visual" type="mesh" rgba="1 1 1 1" mesh="left_wrist_yaw_Link"/>
                          <geom class="visual" type="mesh" rgba="1 1 1 1" mesh="left_hand_palm_Link"/>
                          <geom name="left_hand_collision" class="collision" mesh="left_hand_palm_Link" />
                        </body>
                      </body>
                    </body>
                  </body>
                </body>
              </body>
            </body>
            <body name="right_shoulder_pitch_Link" pos="0.0303 -0.14822 0.28382" quat="0.999048 -0.0436192 0 0">
              <inertial pos="0.00097159 -0.0547742 0.00018343" quat="0.702891 0.710995 -0.0122886 -0.0167424" mass="1.01942" diaginertia="0.00117971 0.000989006 0.00095622"/>
              <joint name="right_shoulder_pitch_joint" pos="0 0 0" axis="0 1 0" range="-2.87979 2.87979" actuatorfrcrange="-60 60" actuatorfrclimited="true" damping="1"/>
              <geom class="visual" type="mesh" rgba="0.1 0.1 0.1 1" mesh="right_shoulder_pitch_Link"/>
              <body name="right_shoulder_roll_Link" pos="0 -0.059 0" quat="0.999048 0.0436192 0 0">
                <inertial pos="0.00086832 -0.00940738 -0.0867344" quat="0.700462 0.0147404 0.0530675 0.711561" mass="0.958523" diaginertia="0.00273751 0.00244941 0.00125173"/>
                <joint name="right_shoulder_roll_joint" pos="0 0 0" axis="1 0 0" range="-2.61799 0.0872665" actuatorfrcrange="-60 60" actuatorfrclimited="true" damping="1"/>
                <geom class="visual" type="mesh" rgba="1 1 1 1" mesh="right_shoulder_roll_Link"/>
                <geom name="right_shoulder_yaw_collision" class="collision" size="0.04 0.046" pos="0 0.01 -0.145" quat="1 0 0 0" type="capsule" rgba="1 0 0 1"/>
                <body name="right_shoulder_yaw_Link" pos="0 -0.01 -0.1475">
                  <inertial pos="0.00413428 0.00146128 -0.0895327" quat="0.715978 -0.0247346 -0.043496 0.696328" mass="0.998599" diaginertia="0.00332583 0.00327983 0.000848304"/>
                  <joint name="right_shoulder_yaw_joint" pos="0 0 0" axis="0 0 1" range="-2.79253 2.79253" actuatorfrcrange="-24 24" actuatorfrclimited="true" damping="1"/>
                  <geom class="visual" type="mesh" rgba="1 1 1 1" mesh="right_shoulder_yaw_Link"/>
                  <body name="right_elbow_Link" pos="0.01 0 -0.133">
                    <inertial pos="0.0776546 0.00122539 -0.0103208" quat="0.0156278 0.711467 -0.0557273 0.700332" mass="0.711878" diaginertia="0.00123618 0.00116622 0.000538053"/>
                    <joint name="right_elbow_joint" pos="0 0 0" axis="0 1 0" range="-0.959931 1.74533" actuatorfrcrange="-24 24" actuatorfrclimited="true" damping="1"/>
                    <geom class="visual" type="mesh" rgba="1 1 1 1" mesh="right_elbow_Link"/>
                    <geom name="right_elbow_yaw_collision" class="collision" size="0.034 0.082" pos="0.08 0 -0.013" quat="0.707106781 0 0.707106781 0" type="capsule" rgba="1 0 0 1"/>
                    <body name="right_wrist_roll_Link" pos="0.129 0 -0.01">
                      <inertial pos="0.0209014 0.00032839 -1.007e-05" quat="0.646384 0.288116 -0.645908 0.286321" mass="0.19186" diaginertia="0.00019562 0.000163226 0.000151184"/>
                      <joint name="right_wrist_roll_joint" pos="0 0 0" axis="1 0 0" range="-2.79253 2.79253" actuatorfrcrange="-24 24" actuatorfrclimited="true" damping="1"/>
                      <geom class="visual" type="mesh" rgba="1 1 1 1" mesh="right_wrist_roll_Link"/>
                      <body name="right_wrist_pitch_Link" pos="0.06 0 0">
                        <inertial pos="0.022825 0.00080274 0.0007711" quat="0.521419 0.496037 0.486247 0.495615" mass="0.567464" diaginertia="0.000515892 0.000514735 0.000233443"/>
                        <joint name="right_wrist_pitch_joint" pos="0 0 0" axis="0 1 0" range="-1.62316 1.62316" actuatorfrcrange="-6 6" actuatorfrclimited="true" damping="1"/>
                        <geom class="visual" type="mesh" rgba="0.1 0.1 0.1 1" mesh="right_wrist_pitch_Link"/>
                        <body name="right_wrist_yaw_Link" pos="0.046 0 0">
                          <inertial pos="0.0967581 0.00348528 0.00444117" quat="0.57118 0.39288 0.583859 0.422501" mass="0.539216" diaginertia="0.00158267 0.00134556 0.000422576"/>
                          <joint name="right_wrist_yaw_joint" pos="0 0 0" axis="0 0 1" range="-1.62316 1.62316" actuatorfrcrange="-6 6" actuatorfrclimited="true" damping="1"/>
                          <geom class="visual" type="mesh" rgba="1 1 1 1" mesh="right_wrist_yaw_Link"/>
                          <geom class="visual" type="mesh" rgba="1 1 1 1" mesh="right_hand_palm_Link"/>
                          <geom name="right_hand_collision" class="collision" mesh="right_hand_palm_Link" />
                        </body>
                      </body>
                    </body>
                  </body>
                </body>
              </body>
            </body>
          </body>
        </body>
      </body>
    </body>
  </worldbody>

  <actuator>
    <motor name="left_hip_pitch_joint" joint="left_hip_pitch_joint"/>
    <motor name="left_hip_roll_joint" joint="left_hip_roll_joint"/>
    <motor name="left_hip_yaw_joint" joint="left_hip_yaw_joint"/>
    <motor name="left_knee_joint" joint="left_knee_joint"/>
    <motor name="left_ankle_pitch_joint" joint="left_ankle_pitch_joint"/>
    <motor name="left_ankle_roll_joint" joint="left_ankle_roll_joint"/>

    <motor name="right_hip_pitch_joint" joint="right_hip_pitch_joint"/>
    <motor name="right_hip_roll_joint" joint="right_hip_roll_joint"/>
    <motor name="right_hip_yaw_joint" joint="right_hip_yaw_joint"/>
    <motor name="right_knee_joint" joint="right_knee_joint"/>
    <motor name="right_ankle_pitch_joint" joint="right_ankle_pitch_joint"/>
    <motor name="right_ankle_roll_joint" joint="right_ankle_roll_joint"/>

    <motor name="waist_yaw_joint" joint="waist_yaw_joint"/>
    <motor name="waist_roll_joint" joint="waist_roll_joint"/>
    <motor name="waist_pitch_joint" joint="waist_pitch_joint"/>
    <motor name="head_yaw_joint" joint="head_yaw_joint"/>

    <motor name="left_shoulder_pitch_joint" joint="left_shoulder_pitch_joint"/>
    <motor name="left_shoulder_roll_joint" joint="left_shoulder_roll_joint"/>
    <motor name="left_shoulder_yaw_joint" joint="left_shoulder_yaw_joint"/>
    <motor name="left_elbow_joint" joint="left_elbow_joint"/>
    <motor name="left_wrist_roll_joint" joint="left_wrist_roll_joint"/>
    <motor name="left_wrist_pitch_joint" joint="left_wrist_pitch_joint"/>
    <motor name="left_wrist_yaw_joint" joint="left_wrist_yaw_joint"/>

    <motor name="right_shoulder_pitch_joint" joint="right_shoulder_pitch_joint"/>
    <motor name="right_shoulder_roll_joint" joint="right_shoulder_roll_joint"/>
    <motor name="right_shoulder_yaw_joint" joint="right_shoulder_yaw_joint"/>
    <motor name="right_elbow_joint" joint="right_elbow_joint"/>
    <motor name="right_wrist_roll_joint" joint="right_wrist_roll_joint"/>
    <motor name="right_wrist_pitch_joint" joint="right_wrist_pitch_joint"/>
    <motor name="right_wrist_yaw_joint" joint="right_wrist_yaw_joint"/>
  </actuator>

  <sensor>
    <jointactuatorfrc name="jointactuatorfrc_left_hip_pitch_joint" joint="left_hip_pitch_joint"/> 
    <jointactuatorfrc name="jointactuatorfrc_left_hip_roll_joint" joint="left_hip_roll_joint"/> 
    <jointactuatorfrc name="jointactuatorfrc_left_hip_yaw_joint" joint="left_hip_yaw_joint"/> 
    <jointactuatorfrc name="jointactuatorfrc_left_knee_joint" joint="left_knee_joint"/> 
    <jointactuatorfrc name="jointactuatorfrc_left_ankle_pitch_joint" joint="left_ankle_pitch_joint"/> 
    <jointactuatorfrc name="jointactuatorfrc_left_ankle_roll_joint" joint="left_ankle_roll_joint"/> 

    <jointactuatorfrc name="jointactuatorfrc_right_hip_pitch_joint" joint="right_hip_pitch_joint"/> 
    <jointactuatorfrc name="jointactuatorfrc_right_hip_roll_joint" joint="right_hip_roll_joint"/> 
    <jointactuatorfrc name="jointactuatorfrc_right_hip_yaw_joint" joint="right_hip_yaw_joint"/> 
    <jointactuatorfrc name="jointactuatorfrc_right_knee_joint" joint="right_knee_joint"/> 
    <jointactuatorfrc name="jointactuatorfrc_right_ankle_pitch_joint" joint="right_ankle_pitch_joint"/> 
    <jointactuatorfrc name="jointactuatorfrc_right_ankle_roll_joint" joint="right_ankle_roll_joint"/> 

    <jointactuatorfrc name="jointactuatorfrc_waist_yaw_joint" joint="waist_yaw_joint"/>
    <jointactuatorfrc name="jointactuatorfrc_waist_roll_joint" joint="waist_roll_joint"/>
    <jointactuatorfrc name="jointactuatorfrc_waist_pitch_joint" joint="waist_pitch_joint"/>

    <jointactuatorfrc name="jointactuatorfrc_left_shoulder_pitch_joint" joint="left_shoulder_pitch_joint"/> 
    <jointactuatorfrc name="jointactuatorfrc_left_shoulder_roll_joint" joint="left_shoulder_roll_joint"/> 
    <jointactuatorfrc name="jointactuatorfrc_left_shoulder_yaw_joint" joint="left_shoulder_yaw_joint"/> 
    <jointactuatorfrc name="jointactuatorfrc_left_elbow_joint" joint="left_elbow_joint"/> 
    <jointactuatorfrc name="jointactuatorfrc_left_wrist_roll_joint" joint="left_wrist_roll_joint"/> 
    <jointactuatorfrc name="jointactuatorfrc_left_wrist_pitch_joint" joint="left_wrist_pitch_joint"/> 
    <jointactuatorfrc name="jointactuatorfrc_left_wrist_yaw_joint" joint="left_wrist_yaw_joint"/> 

    <jointactuatorfrc name="jointactuatorfrc_right_shoulder_pitch_joint" joint="right_shoulder_pitch_joint"/> 
    <jointactuatorfrc name="jointactuatorfrc_right_shoulder_roll_joint" joint="right_shoulder_roll_joint"/> 
    <jointactuatorfrc name="jointactuatorfrc_right_shoulder_yaw_joint" joint="right_shoulder_yaw_joint"/> 
    <jointactuatorfrc name="jointactuatorfrc_right_elbow_joint" joint="right_elbow_joint"/> 
    <jointactuatorfrc name="jointactuatorfrc_right_wrist_roll_joint" joint="right_wrist_roll_joint"/> 
    <jointactuatorfrc name="jointactuatorfrc_right_wrist_pitch_joint" joint="right_wrist_pitch_joint"/> 
    <jointactuatorfrc name="jointactuatorfrc_right_wrist_yaw_joint" joint="right_wrist_yaw_joint"/>

    <jointpos name="jointpos_left_hip_pitch_joint" joint="left_hip_pitch_joint"/>
    <jointpos name="jointpos_left_hip_roll_joint" joint="left_hip_roll_joint"/>
    <jointpos name="jointpos_left_hip_yaw_joint" joint="left_hip_yaw_joint"/>
    <jointpos name="jointpos_left_knee_joint" joint="left_knee_joint"/>
    <jointpos name="jointpos_left_ankle_pitch_joint" joint="left_ankle_pitch_joint"/>
    <jointpos name="jointpos_left_ankle_roll_joint" joint="left_ankle_roll_joint"/>

    <jointpos name="jointpos_right_hip_pitch_joint" joint="right_hip_pitch_joint"/>
    <jointpos name="jointpos_right_hip_roll_joint" joint="right_hip_roll_joint"/>
    <jointpos name="jointpos_right_hip_yaw_joint" joint="right_hip_yaw_joint"/>
    <jointpos name="jointpos_right_knee_joint" joint="right_knee_joint"/>
    <jointpos name="jointpos_right_ankle_pitch_joint" joint="right_ankle_pitch_joint"/>
    <jointpos name="jointpos_right_ankle_roll_joint" joint="right_ankle_roll_joint"/>

    <jointpos name="jointpos_waist_yaw_joint" joint="waist_yaw_joint"/>
    <jointpos name="jointpos_waist_roll_joint" joint="waist_roll_joint"/>
    <jointpos name="jointpos_waist_pitch_joint" joint="waist_pitch_joint"/>

    <jointpos name="jointpos_left_shoulder_pitch_joint" joint="left_shoulder_pitch_joint"/>
    <jointpos name="jointpos_left_shoulder_roll_joint" joint="left_shoulder_roll_joint"/>
    <jointpos name="jointpos_left_shoulder_yaw_joint" joint="left_shoulder_yaw_joint"/>
    <jointpos name="jointpos_left_elbow_joint" joint="left_elbow_joint"/>
    <jointpos name="jointpos_left_wrist_roll_joint" joint="left_wrist_roll_joint"/>
    <jointpos name="jointpos_left_wrist_pitch_joint" joint="left_wrist_pitch_joint"/>
    <jointpos name="jointpos_left_wrist_yaw_joint" joint="left_wrist_yaw_joint"/>

    <jointpos name="jointpos_right_shoulder_pitch_joint" joint="right_shoulder_pitch_joint"/>
    <jointpos name="jointpos_right_shoulder_roll_joint" joint="right_shoulder_roll_joint"/>
    <jointpos name="jointpos_right_shoulder_yaw_joint" joint="right_shoulder_yaw_joint"/>
    <jointpos name="jointpos_right_elbow_joint" joint="right_elbow_joint"/>
    <jointpos name="jointpos_right_wrist_roll_joint" joint="right_wrist_roll_joint"/>
    <jointpos name="jointpos_right_wrist_pitch_joint" joint="right_wrist_pitch_joint"/>
    <jointpos name="jointpos_right_wrist_yaw_joint" joint="right_wrist_yaw_joint"/>

    <jointvel name="jointvel_left_hip_pitch_joint" joint="left_hip_pitch_joint"/>
    <jointvel name="jointvel_left_hip_roll_joint" joint="left_hip_roll_joint"/>
    <jointvel name="jointvel_left_hip_yaw_joint" joint="left_hip_yaw_joint"/>
    <jointvel name="jointvel_left_knee_joint" joint="left_knee_joint"/>
    <jointvel name="jointvel_left_ankle_pitch_joint" joint="left_ankle_pitch_joint"/>
    <jointvel name="jointvel_left_ankle_roll_joint" joint="left_ankle_roll_joint"/>

    <jointvel name="jointvel_right_hip_pitch_joint" joint="right_hip_pitch_joint"/>
    <jointvel name="jointvel_right_hip_roll_joint" joint="right_hip_roll_joint"/>
    <jointvel name="jointvel_right_hip_yaw_joint" joint="right_hip_yaw_joint"/>
    <jointvel name="jointvel_right_knee_joint" joint="right_knee_joint"/>
    <jointvel name="jointvel_right_ankle_pitch_joint" joint="right_ankle_pitch_joint"/>
    <jointvel name="jointvel_right_ankle_roll_joint" joint="right_ankle_roll_joint"/>

    <jointvel name="jointvel_waist_roll_joint" joint="waist_roll_joint"/>
    <jointvel name="jointvel_waist_pitch_joint" joint="waist_pitch_joint"/>
    <jointvel name="jointvel_waist_yaw_joint" joint="waist_yaw_joint"/>

    <jointvel name="jointvel_left_shoulder_pitch_joint" joint="left_shoulder_pitch_joint"/>
    <jointvel name="jointvel_left_shoulder_roll_joint" joint="left_shoulder_roll_joint"/>
    <jointvel name="jointvel_left_shoulder_yaw_joint" joint="left_shoulder_yaw_joint"/>
    <jointvel name="jointvel_left_elbow_joint" joint="left_elbow_joint"/>
    <jointvel name="jointvel_left_wrist_roll_joint" joint="left_wrist_roll_joint"/>
    <jointvel name="jointvel_left_wrist_pitch_joint" joint="left_wrist_pitch_joint"/>
    <jointvel name="jointvel_left_wrist_yaw_joint" joint="left_wrist_yaw_joint"/>

    <jointvel name="jointvel_right_shoulder_pitch_joint" joint="right_shoulder_pitch_joint"/>
    <jointvel name="jointvel_right_shoulder_roll_joint" joint="right_shoulder_roll_joint"/>
    <jointvel name="jointvel_right_shoulder_yaw_joint" joint="right_shoulder_yaw_joint"/>
    <jointvel name="jointvel_right_elbow_joint" joint="right_elbow_joint"/>
    <jointvel name="jointvel_right_wrist_roll_joint" joint="right_wrist_roll_joint"/>
    <jointvel name="jointvel_right_wrist_pitch_joint" joint="right_wrist_pitch_joint"/>
    <jointvel name="jointvel_right_wrist_yaw_joint" joint="right_wrist_yaw_joint"/>

    <force name="left_foot_force" site="left_foot"/>
    <torque name="left_foot_torque" site="left_foot"/>

    <force name="right_foot_force" site="right_foot"/>
    <torque name="right_foot_torque" site="right_foot"/>

    <framequat name="body-orientation" objtype="site" objname="imu_in_pelvis" noise="0" />
    <gyro name="body-angular-velocity" site="imu_in_pelvis" noise="0.001" />
    <framepos name="body-linear-pos" objtype="site" objname="imu_in_pelvis" />
    <velocimeter name="body-linear-vel" site="imu_in_pelvis" />
    <accelerometer name="body-linear-acceleration" site="imu_in_pelvis" noise="0.001" />

    <framequat name="torso-orientation" objtype="site" objname="imu_in_torso" noise="0" />
    <gyro name="torso-angular-velocity" site="imu_in_torso" noise="0.001" />
    <framepos name="torso-linear-pos" objtype="site" objname="imu_in_torso" />
    <velocimeter name="torso-linear-vel" site="imu_in_torso" />
    <accelerometer name="torso-linear-acceleration" site="imu_in_torso" noise="0.001" />

    <subtreeangmom name="root_angmom" body="pelvis_link"/>
  </sensor>

  <contact>
    <exclude body1="left_elbow_Link" body2="left_wrist_pitch_Link"/>
    <exclude body1="right_elbow_Link" body2="right_wrist_pitch_Link"/>
    <exclude body1="pelvis_link" body2="right_hip_roll_Link"/>
    <exclude body1="pelvis_link" body2="left_hip_roll_Link"/>
    <exclude body1="pelvis_link" body2="right_hip_pitch_Link"/>
    <exclude body1="pelvis_link" body2="left_hip_pitch_Link"/>
  </contact>
  <keyframe>
    <key name="home_default" qpos='-0.0480897 -0.000148882 1.08762 1 3.23293e-06 -0.000461713 0.000723722 -0.130784 0.00672637 -0.0349827 0.251973 -0.124826 -0.00886943 -0.130791 -0.00673043 0.0349834 0.251996 -0.124841 0.00886255 -4.69459e-07 0.000327523 0.00925116 0.10911 0.295356 0.113002 -0.00213452 0.80466 -2.69937e-07 0.00403502 -0.000684321 0.295464 -0.11314 0.00208014 0.804774 -0.000127647 0.0044826 0.000280109'/>
  </keyframe>
</mujoco>
